Predict error file = D:\Dataset_and_Demo\2015-02-25_to_2015-05-31\04657_ADMeanFused_Trans.tif
Traceback (most recent call last):
  File "d:\09_Code\Gis_Script\05_SAM\º‡Ã˝SAM.py", line 50, in process_file
    AOI_Bound_Info = json.load(f)
                     ^^^^^^^^^^^^
  File "D:\Wrz\anaconda\envs\GEE\Lib\json\__init__.py", line 293, in load
    return loads(fp.read(),
           ^^^^^^^^^^^^^^^^
  File "D:\Wrz\anaconda\envs\GEE\Lib\json\__init__.py", line 346, in loads
    return _default_decoder.decode(s)
           ^^^^^^^^^^^^^^^^^^^^^^^^^^
  File "D:\Wrz\anaconda\envs\GEE\Lib\json\decoder.py", line 337, in decode
    obj, end = self.raw_decode(s, idx=_w(s, 0).end())
               ^^^^^^^^^^^^^^^^^^^^^^^^^^^^^^^^^^^^^^
  File "D:\Wrz\anaconda\envs\GEE\Lib\json\decoder.py", line 355, in raw_decode
    raise JSONDecodeError("Expecting value", s, err.value) from None
json.decoder.JSONDecodeError: Expecting value: line 1 column 1 (char 0)

Predict error file = D:\Dataset_and_Demo\2015-05-31_to_2015-09-15\00304_ADMeanFused_Trans.tif
Traceback (most recent call last):
  File "d:\09_Code\Gis_Script\05_SAM\º‡Ã˝SAM.py", line 50, in process_file
    AOI_Bound_Info = json.load(f)
                     ^^^^^^^^^^^^
  File "D:\Wrz\anaconda\envs\GEE\Lib\json\__init__.py", line 293, in load
    return loads(fp.read(),
           ^^^^^^^^^^^^^^^^
  File "D:\Wrz\anaconda\envs\GEE\Lib\json\__init__.py", line 346, in loads
    return _default_decoder.decode(s)
           ^^^^^^^^^^^^^^^^^^^^^^^^^^
  File "D:\Wrz\anaconda\envs\GEE\Lib\json\decoder.py", line 337, in decode
    obj, end = self.raw_decode(s, idx=_w(s, 0).end())
               ^^^^^^^^^^^^^^^^^^^^^^^^^^^^^^^^^^^^^^
  File "D:\Wrz\anaconda\envs\GEE\Lib\json\decoder.py", line 355, in raw_decode
    raise JSONDecodeError("Expecting value", s, err.value) from None
json.decoder.JSONDecodeError: Expecting value: line 1 column 1 (char 0)

Predict error file = D:\Dataset_and_Demo\2015-05-31_to_2015-09-15\00306_ADMeanFused_Trans.tif
Traceback (most recent call last):
  File "d:\09_Code\Gis_Script\05_SAM\º‡Ã˝SAM.py", line 50, in process_file
    AOI_Bound_Info = json.load(f)
                     ^^^^^^^^^^^^
  File "D:\Wrz\anaconda\envs\GEE\Lib\json\__init__.py", line 293, in load
    return loads(fp.read(),
           ^^^^^^^^^^^^^^^^
  File "D:\Wrz\anaconda\envs\GEE\Lib\json\__init__.py", line 346, in loads
    return _default_decoder.decode(s)
           ^^^^^^^^^^^^^^^^^^^^^^^^^^
  File "D:\Wrz\anaconda\envs\GEE\Lib\json\decoder.py", line 337, in decode
    obj, end = self.raw_decode(s, idx=_w(s, 0).end())
               ^^^^^^^^^^^^^^^^^^^^^^^^^^^^^^^^^^^^^^
  File "D:\Wrz\anaconda\envs\GEE\Lib\json\decoder.py", line 355, in raw_decode
    raise JSONDecodeError("Expecting value", s, err.value) from None
json.decoder.JSONDecodeError: Expecting value: line 1 column 1 (char 0)

Predict error file = D:\Dataset_and_Demo\2015-09-15_to_2015-11-28\01791_ADMeanFused_Trans.tif
Traceback (most recent call last):
  File "d:\09_Code\Gis_Script\05_SAM\º‡Ã˝SAM.py", line 50, in process_file
    AOI_Bound_Info = json.load(f)
                     ^^^^^^^^^^^^
  File "D:\Wrz\anaconda\envs\GEE\Lib\json\__init__.py", line 293, in load
    return loads(fp.read(),
           ^^^^^^^^^^^^^^^^
  File "D:\Wrz\anaconda\envs\GEE\Lib\json\__init__.py", line 346, in loads
    return _default_decoder.decode(s)
           ^^^^^^^^^^^^^^^^^^^^^^^^^^
  File "D:\Wrz\anaconda\envs\GEE\Lib\json\decoder.py", line 337, in decode
    obj, end = self.raw_decode(s, idx=_w(s, 0).end())
               ^^^^^^^^^^^^^^^^^^^^^^^^^^^^^^^^^^^^^^
  File "D:\Wrz\anaconda\envs\GEE\Lib\json\decoder.py", line 355, in raw_decode
    raise JSONDecodeError("Expecting value", s, err.value) from None
json.decoder.JSONDecodeError: Expecting value: line 1 column 1 (char 0)

Predict error file = D:\Dataset_and_Demo\2015-09-15_to_2015-11-28\01801_ADMeanFused_WithTiles_Trans.tif
Traceback (most recent call last):
  File "d:\09_Code\Gis_Script\05_SAM\º‡Ã˝SAM.py", line 57, in process_file
    sam.predict(boxes=boxes, point_crs="EPSG:4326", output=output_path, dtype="uint8")
  File "D:\Wrz\anaconda\envs\GEE\Lib\site-packages\samgeo\samgeo.py", line 581, in predict
    if isinstance(coords[0], int):
                  ~~~~~~^^^
TypeError: 'NoneType' object is not subscriptable

Predict error file = D:\Dataset_and_Demo\2015-09-15_to_2015-11-28\01817_ADMeanFused_WithTiles_Trans.tif
Traceback (most recent call last):
  File "d:\09_Code\Gis_Script\05_SAM\º‡Ã˝SAM.py", line 57, in process_file
    sam.predict(boxes=boxes, point_crs="EPSG:4326", output=output_path, dtype="uint8")
  File "D:\Wrz\anaconda\envs\GEE\Lib\site-packages\samgeo\samgeo.py", line 581, in predict
    if isinstance(coords[0], int):
                  ~~~~~~^^^
TypeError: 'NoneType' object is not subscriptable

Predict error file = D:\Dataset_and_Demo\2015-09-15_to_2015-11-28\01819_ADMeanFused_WithTiles_Trans.tif
Traceback (most recent call last):
  File "d:\09_Code\Gis_Script\05_SAM\º‡Ã˝SAM.py", line 57, in process_file
    sam.predict(boxes=boxes, point_crs="EPSG:4326", output=output_path, dtype="uint8")
  File "D:\Wrz\anaconda\envs\GEE\Lib\site-packages\samgeo\samgeo.py", line 581, in predict
    if isinstance(coords[0], int):
                  ~~~~~~^^^
TypeError: 'NoneType' object is not subscriptable

Predict error file = D:\Dataset_and_Demo\2015-09-15_to_2015-11-28\01827_ADMeanFused_WithTiles_Trans.tif
Traceback (most recent call last):
  File "d:\09_Code\Gis_Script\05_SAM\º‡Ã˝SAM.py", line 57, in process_file
    sam.predict(boxes=boxes, point_crs="EPSG:4326", output=output_path, dtype="uint8")
  File "D:\Wrz\anaconda\envs\GEE\Lib\site-packages\samgeo\samgeo.py", line 581, in predict
    if isinstance(coords[0], int):
                  ~~~~~~^^^
TypeError: 'NoneType' object is not subscriptable

Predict error file = D:\Dataset_and_Demo\2015-09-15_to_2015-11-28\01862_ADMeanFused_WithTiles_Trans.tif
Traceback (most recent call last):
  File "d:\09_Code\Gis_Script\05_SAM\º‡Ã˝SAM.py", line 57, in process_file
    sam.predict(boxes=boxes, point_crs="EPSG:4326", output=output_path, dtype="uint8")
  File "D:\Wrz\anaconda\envs\GEE\Lib\site-packages\samgeo\samgeo.py", line 581, in predict
    if isinstance(coords[0], int):
                  ~~~~~~^^^
TypeError: 'NoneType' object is not subscriptable

Predict error file = D:\Dataset_and_Demo\2017-05-31_to_2017-09-15\00234_ADMeanFused_WithTiles_Trans.tif
Traceback (most recent call last):
  File "d:\09_Code\Gis_Script\05_SAM\º‡Ã˝SAM.py", line 57, in process_file
    sam.predict(boxes=boxes, point_crs="EPSG:4326", output=output_path, dtype="uint8")
  File "D:\Wrz\anaconda\envs\GEE\Lib\site-packages\samgeo\samgeo.py", line 581, in predict
    if isinstance(coords[0], int):
                  ~~~~~~^^^
TypeError: 'NoneType' object is not subscriptable

Predict error file = D:\Dataset_and_Demo\2017-05-31_to_2017-09-15\00235_ADMeanFused_WithTiles_Trans.tif
Traceback (most recent call last):
  File "d:\09_Code\Gis_Script\05_SAM\º‡Ã˝SAM.py", line 57, in process_file
    sam.predict(boxes=boxes, point_crs="EPSG:4326", output=output_path, dtype="uint8")
  File "D:\Wrz\anaconda\envs\GEE\Lib\site-packages\samgeo\samgeo.py", line 581, in predict
    if isinstance(coords[0], int):
                  ~~~~~~^^^
TypeError: 'NoneType' object is not subscriptable

Predict error file = D:\Dataset_and_Demo\2017-05-31_to_2017-09-15\00240_ADMeanFused_WithTiles_Trans.tif
Traceback (most recent call last):
  File "d:\09_Code\Gis_Script\05_SAM\º‡Ã˝SAM.py", line 57, in process_file
    sam.predict(boxes=boxes, point_crs="EPSG:4326", output=output_path, dtype="uint8")
  File "D:\Wrz\anaconda\envs\GEE\Lib\site-packages\samgeo\samgeo.py", line 581, in predict
    if isinstance(coords[0], int):
                  ~~~~~~^^^
TypeError: 'NoneType' object is not subscriptable

Predict error file = D:\Dataset_and_Demo\2017-05-31_to_2017-09-15\00261_ADMeanFused_WithTiles_Trans.tif
Traceback (most recent call last):
  File "d:\09_Code\Gis_Script\05_SAM\º‡Ã˝SAM.py", line 57, in process_file
    sam.predict(boxes=boxes, point_crs="EPSG:4326", output=output_path, dtype="uint8")
  File "D:\Wrz\anaconda\envs\GEE\Lib\site-packages\samgeo\samgeo.py", line 581, in predict
    if isinstance(coords[0], int):
                  ~~~~~~^^^
TypeError: 'NoneType' object is not subscriptable

Predict error file = D:\Dataset_and_Demo\2017-05-31_to_2017-09-15\00263_ADMeanFused_WithTiles_Trans.tif
Traceback (most recent call last):
  File "d:\09_Code\Gis_Script\05_SAM\º‡Ã˝SAM.py", line 57, in process_file
    sam.predict(boxes=boxes, point_crs="EPSG:4326", output=output_path, dtype="uint8")
  File "D:\Wrz\anaconda\envs\GEE\Lib\site-packages\samgeo\samgeo.py", line 581, in predict
    if isinstance(coords[0], int):
                  ~~~~~~^^^
TypeError: 'NoneType' object is not subscriptable

Predict error file = D:\Dataset_and_Demo\2017-05-31_to_2017-09-15\00264_ADMeanFused_WithTiles_Trans.tif
Traceback (most recent call last):
  File "d:\09_Code\Gis_Script\05_SAM\º‡Ã˝SAM.py", line 57, in process_file
    sam.predict(boxes=boxes, point_crs="EPSG:4326", output=output_path, dtype="uint8")
  File "D:\Wrz\anaconda\envs\GEE\Lib\site-packages\samgeo\samgeo.py", line 581, in predict
    if isinstance(coords[0], int):
                  ~~~~~~^^^
TypeError: 'NoneType' object is not subscriptable

Predict error file = D:\Dataset_and_Demo\2017-05-31_to_2017-09-15\00269_ADMeanFused_WithTiles_Trans.tif
Traceback (most recent call last):
  File "d:\09_Code\Gis_Script\05_SAM\º‡Ã˝SAM.py", line 57, in process_file
    sam.predict(boxes=boxes, point_crs="EPSG:4326", output=output_path, dtype="uint8")
  File "D:\Wrz\anaconda\envs\GEE\Lib\site-packages\samgeo\samgeo.py", line 581, in predict
    if isinstance(coords[0], int):
                  ~~~~~~^^^
TypeError: 'NoneType' object is not subscriptable

Predict error file = D:\Dataset_and_Demo\2017-05-31_to_2017-09-15\00357_ADMeanFused_WithTiles_Trans.tif
Traceback (most recent call last):
  File "d:\09_Code\Gis_Script\05_SAM\º‡Ã˝SAM.py", line 57, in process_file
    sam.predict(boxes=boxes, point_crs="EPSG:4326", output=output_path, dtype="uint8")
  File "D:\Wrz\anaconda\envs\GEE\Lib\site-packages\samgeo\samgeo.py", line 581, in predict
    if isinstance(coords[0], int):
                  ~~~~~~^^^
TypeError: 'NoneType' object is not subscriptable

Predict error file = D:\Dataset_and_Demo\2018-02-25_to_2018-05-31\02432_ADMeanFused_WithTiles_Trans.tif
Traceback (most recent call last):
  File "d:\09_Code\Gis_Script\05_SAM\º‡Ã˝SAM.py", line 57, in process_file
    sam.predict(boxes=boxes, point_crs="EPSG:4326", output=output_path, dtype="uint8")
  File "D:\Wrz\anaconda\envs\GEE\Lib\site-packages\samgeo\samgeo.py", line 581, in predict
    if isinstance(coords[0], int):
                  ~~~~~~^^^
TypeError: 'NoneType' object is not subscriptable

Predict error file = D:\Dataset_and_Demo\2018-02-25_to_2018-05-31\02434_ADMeanFused_WithTiles_Trans.tif
Traceback (most recent call last):
  File "d:\09_Code\Gis_Script\05_SAM\º‡Ã˝SAM.py", line 57, in process_file
    sam.predict(boxes=boxes, point_crs="EPSG:4326", output=output_path, dtype="uint8")
  File "D:\Wrz\anaconda\envs\GEE\Lib\site-packages\samgeo\samgeo.py", line 581, in predict
    if isinstance(coords[0], int):
                  ~~~~~~^^^
TypeError: 'NoneType' object is not subscriptable

Predict error file = D:\Dataset_and_Demo\2018-02-25_to_2018-05-31\02436_ADMeanFused_WithTiles_Trans.tif
Traceback (most recent call last):
  File "d:\09_Code\Gis_Script\05_SAM\º‡Ã˝SAM.py", line 57, in process_file
    sam.predict(boxes=boxes, point_crs="EPSG:4326", output=output_path, dtype="uint8")
  File "D:\Wrz\anaconda\envs\GEE\Lib\site-packages\samgeo\samgeo.py", line 581, in predict
    if isinstance(coords[0], int):
                  ~~~~~~^^^
TypeError: 'NoneType' object is not subscriptable

Predict error file = D:\Dataset_and_Demo\2018-02-25_to_2018-05-31\02441_ADMeanFused_WithTiles_Trans.tif
Traceback (most recent call last):
  File "d:\09_Code\Gis_Script\05_SAM\º‡Ã˝SAM.py", line 57, in process_file
    sam.predict(boxes=boxes, point_crs="EPSG:4326", output=output_path, dtype="uint8")
  File "D:\Wrz\anaconda\envs\GEE\Lib\site-packages\samgeo\samgeo.py", line 581, in predict
    if isinstance(coords[0], int):
                  ~~~~~~^^^
TypeError: 'NoneType' object is not subscriptable

Predict error file = D:\Dataset_and_Demo\2018-02-25_to_2018-05-31\02472_ADMeanFused_WithTiles_Trans.tif
Traceback (most recent call last):
  File "d:\09_Code\Gis_Script\05_SAM\º‡Ã˝SAM.py", line 57, in process_file
    sam.predict(boxes=boxes, point_crs="EPSG:4326", output=output_path, dtype="uint8")
  File "D:\Wrz\anaconda\envs\GEE\Lib\site-packages\samgeo\samgeo.py", line 581, in predict
    if isinstance(coords[0], int):
                  ~~~~~~^^^
TypeError: 'NoneType' object is not subscriptable

Predict error file = D:\Dataset_and_Demo\2018-02-25_to_2018-05-31\02484_ADMeanFused_WithTiles_Trans.tif
Traceback (most recent call last):
  File "d:\09_Code\Gis_Script\05_SAM\º‡Ã˝SAM.py", line 57, in process_file
    sam.predict(boxes=boxes, point_crs="EPSG:4326", output=output_path, dtype="uint8")
  File "D:\Wrz\anaconda\envs\GEE\Lib\site-packages\samgeo\samgeo.py", line 581, in predict
    if isinstance(coords[0], int):
                  ~~~~~~^^^
TypeError: 'NoneType' object is not subscriptable

Predict error file = D:\Dataset_and_Demo\2019-09-15_to_2019-11-28\00434_ADMeanFused_WithTiles_Trans.tif
Traceback (most recent call last):
  File "d:\09_Code\Gis_Script\05_SAM\º‡Ã˝SAM.py", line 57, in process_file
    sam.predict(boxes=boxes, point_crs="EPSG:4326", output=output_path, dtype="uint8")
  File "D:\Wrz\anaconda\envs\GEE\Lib\site-packages\samgeo\samgeo.py", line 581, in predict
    if isinstance(coords[0], int):
                  ~~~~~~^^^
TypeError: 'NoneType' object is not subscriptable

Predict error file = D:\Dataset_and_Demo\2019-09-15_to_2019-11-28\00439_ADMeanFused_WithTiles_Trans.tif
Traceback (most recent call last):
  File "d:\09_Code\Gis_Script\05_SAM\º‡Ã˝SAM.py", line 57, in process_file
    sam.predict(boxes=boxes, point_crs="EPSG:4326", output=output_path, dtype="uint8")
  File "D:\Wrz\anaconda\envs\GEE\Lib\site-packages\samgeo\samgeo.py", line 581, in predict
    if isinstance(coords[0], int):
                  ~~~~~~^^^
TypeError: 'NoneType' object is not subscriptable

Predict error file = D:\Dataset_and_Demo\2019-09-15_to_2019-11-28\00526_ADMeanFused_WithTiles_Trans.tif
Traceback (most recent call last):
  File "d:\09_Code\Gis_Script\05_SAM\º‡Ã˝SAM.py", line 57, in process_file
    sam.predict(boxes=boxes, point_crs="EPSG:4326", output=output_path, dtype="uint8")
  File "D:\Wrz\anaconda\envs\GEE\Lib\site-packages\samgeo\samgeo.py", line 581, in predict
    if isinstance(coords[0], int):
                  ~~~~~~^^^
TypeError: 'NoneType' object is not subscriptable

Predict error file = D:\Dataset_and_Demo\2020-02-25_to_2020-05-31\02462_ADMeanFused_WithTiles_Trans.tif
Traceback (most recent call last):
  File "d:\09_Code\Gis_Script\05_SAM\º‡Ã˝SAM.py", line 57, in process_file
    sam.predict(boxes=boxes, point_crs="EPSG:4326", output=output_path, dtype="uint8")
  File "D:\Wrz\anaconda\envs\GEE\Lib\site-packages\samgeo\samgeo.py", line 581, in predict
    if isinstance(coords[0], int):
                  ~~~~~~^^^
TypeError: 'NoneType' object is not subscriptable

Predict error file = D:\Dataset_and_Demo\2020-02-25_to_2020-05-31\02464_ADMeanFused_WithTiles_Trans.tif
Traceback (most recent call last):
  File "d:\09_Code\Gis_Script\05_SAM\º‡Ã˝SAM.py", line 50, in process_file
    AOI_Bound_Info = json.load(f)
                     ^^^^^^^^^^^^
  File "D:\Wrz\anaconda\envs\GEE\Lib\json\__init__.py", line 293, in load
    return loads(fp.read(),
           ^^^^^^^^^^^^^^^^
  File "D:\Wrz\anaconda\envs\GEE\Lib\json\__init__.py", line 346, in loads
    return _default_decoder.decode(s)
           ^^^^^^^^^^^^^^^^^^^^^^^^^^
  File "D:\Wrz\anaconda\envs\GEE\Lib\json\decoder.py", line 337, in decode
    obj, end = self.raw_decode(s, idx=_w(s, 0).end())
               ^^^^^^^^^^^^^^^^^^^^^^^^^^^^^^^^^^^^^^
  File "D:\Wrz\anaconda\envs\GEE\Lib\json\decoder.py", line 355, in raw_decode
    raise JSONDecodeError("Expecting value", s, err.value) from None
json.decoder.JSONDecodeError: Expecting value: line 1 column 1 (char 0)

Predict error file = D:\Dataset_and_Demo\2020-02-25_to_2020-05-31\02466_ADMeanFused_WithTiles_Trans.tif
Traceback (most recent call last):
  File "d:\09_Code\Gis_Script\05_SAM\º‡Ã˝SAM.py", line 57, in process_file
    sam.predict(boxes=boxes, point_crs="EPSG:4326", output=output_path, dtype="uint8")
  File "D:\Wrz\anaconda\envs\GEE\Lib\site-packages\samgeo\samgeo.py", line 581, in predict
    if isinstance(coords[0], int):
                  ~~~~~~^^^
TypeError: 'NoneType' object is not subscriptable

Predict error file = D:\Dataset_and_Demo\2020-02-25_to_2020-05-31\02487_ADMeanFused_WithTiles_Trans.tif
Traceback (most recent call last):
  File "d:\09_Code\Gis_Script\05_SAM\º‡Ã˝SAM.py", line 57, in process_file
    sam.predict(boxes=boxes, point_crs="EPSG:4326", output=output_path, dtype="uint8")
  File "D:\Wrz\anaconda\envs\GEE\Lib\site-packages\samgeo\samgeo.py", line 581, in predict
    if isinstance(coords[0], int):
                  ~~~~~~^^^
TypeError: 'NoneType' object is not subscriptable

Predict error file = D:\Dataset_and_Demo\2020-02-25_to_2020-05-31\02571_ADMeanFused_WithTiles_Trans.tif
Traceback (most recent call last):
  File "d:\09_Code\Gis_Script\05_SAM\º‡Ã˝SAM.py", line 57, in process_file
    sam.predict(boxes=boxes, point_crs="EPSG:4326", output=output_path, dtype="uint8")
  File "D:\Wrz\anaconda\envs\GEE\Lib\site-packages\samgeo\samgeo.py", line 581, in predict
    if isinstance(coords[0], int):
                  ~~~~~~^^^
TypeError: 'NoneType' object is not subscriptable

Predict error file = D:\Dataset_and_Demo\2015-02-25_to_2015-05-31\04657_ADMeanFused_Trans.tif
Traceback (most recent call last):
  File "d:\09_Code\Gis_Script\05_SAM\º‡Ã˝SAM.py", line 50, in process_file
    AOI_Bound_Info = json.load(f)
                     ^^^^^^^^^^^^
  File "D:\Wrz\anaconda\envs\GEE\Lib\json\__init__.py", line 293, in load
    return loads(fp.read(),
           ^^^^^^^^^^^^^^^^
  File "D:\Wrz\anaconda\envs\GEE\Lib\json\__init__.py", line 346, in loads
    return _default_decoder.decode(s)
           ^^^^^^^^^^^^^^^^^^^^^^^^^^
  File "D:\Wrz\anaconda\envs\GEE\Lib\json\decoder.py", line 337, in decode
    obj, end = self.raw_decode(s, idx=_w(s, 0).end())
               ^^^^^^^^^^^^^^^^^^^^^^^^^^^^^^^^^^^^^^
  File "D:\Wrz\anaconda\envs\GEE\Lib\json\decoder.py", line 355, in raw_decode
    raise JSONDecodeError("Expecting value", s, err.value) from None
json.decoder.JSONDecodeError: Expecting value: line 1 column 1 (char 0)

Predict error file = D:\Dataset_and_Demo\2015-05-31_to_2015-09-15\00304_ADMeanFused_Trans.tif
Traceback (most recent call last):
  File "d:\09_Code\Gis_Script\05_SAM\º‡Ã˝SAM.py", line 50, in process_file
    AOI_Bound_Info = json.load(f)
                     ^^^^^^^^^^^^
  File "D:\Wrz\anaconda\envs\GEE\Lib\json\__init__.py", line 293, in load
    return loads(fp.read(),
           ^^^^^^^^^^^^^^^^
  File "D:\Wrz\anaconda\envs\GEE\Lib\json\__init__.py", line 346, in loads
    return _default_decoder.decode(s)
           ^^^^^^^^^^^^^^^^^^^^^^^^^^
  File "D:\Wrz\anaconda\envs\GEE\Lib\json\decoder.py", line 337, in decode
    obj, end = self.raw_decode(s, idx=_w(s, 0).end())
               ^^^^^^^^^^^^^^^^^^^^^^^^^^^^^^^^^^^^^^
  File "D:\Wrz\anaconda\envs\GEE\Lib\json\decoder.py", line 355, in raw_decode
    raise JSONDecodeError("Expecting value", s, err.value) from None
json.decoder.JSONDecodeError: Expecting value: line 1 column 1 (char 0)

Predict error file = D:\Dataset_and_Demo\2015-05-31_to_2015-09-15\00306_ADMeanFused_Trans.tif
Traceback (most recent call last):
  File "d:\09_Code\Gis_Script\05_SAM\º‡Ã˝SAM.py", line 50, in process_file
    AOI_Bound_Info = json.load(f)
                     ^^^^^^^^^^^^
  File "D:\Wrz\anaconda\envs\GEE\Lib\json\__init__.py", line 293, in load
    return loads(fp.read(),
           ^^^^^^^^^^^^^^^^
  File "D:\Wrz\anaconda\envs\GEE\Lib\json\__init__.py", line 346, in loads
    return _default_decoder.decode(s)
           ^^^^^^^^^^^^^^^^^^^^^^^^^^
  File "D:\Wrz\anaconda\envs\GEE\Lib\json\decoder.py", line 337, in decode
    obj, end = self.raw_decode(s, idx=_w(s, 0).end())
               ^^^^^^^^^^^^^^^^^^^^^^^^^^^^^^^^^^^^^^
  File "D:\Wrz\anaconda\envs\GEE\Lib\json\decoder.py", line 355, in raw_decode
    raise JSONDecodeError("Expecting value", s, err.value) from None
json.decoder.JSONDecodeError: Expecting value: line 1 column 1 (char 0)

Predict error file = D:\Dataset_and_Demo\2015-09-15_to_2015-11-28\01791_ADMeanFused_Trans.tif
Traceback (most recent call last):
  File "d:\09_Code\Gis_Script\05_SAM\º‡Ã˝SAM.py", line 50, in process_file
    AOI_Bound_Info = json.load(f)
                     ^^^^^^^^^^^^
  File "D:\Wrz\anaconda\envs\GEE\Lib\json\__init__.py", line 293, in load
    return loads(fp.read(),
           ^^^^^^^^^^^^^^^^
  File "D:\Wrz\anaconda\envs\GEE\Lib\json\__init__.py", line 346, in loads
    return _default_decoder.decode(s)
           ^^^^^^^^^^^^^^^^^^^^^^^^^^
  File "D:\Wrz\anaconda\envs\GEE\Lib\json\decoder.py", line 337, in decode
    obj, end = self.raw_decode(s, idx=_w(s, 0).end())
               ^^^^^^^^^^^^^^^^^^^^^^^^^^^^^^^^^^^^^^
  File "D:\Wrz\anaconda\envs\GEE\Lib\json\decoder.py", line 355, in raw_decode
    raise JSONDecodeError("Expecting value", s, err.value) from None
json.decoder.JSONDecodeError: Expecting value: line 1 column 1 (char 0)

Predict error file = D:\Dataset_and_Demo\2015-09-15_to_2015-11-28\01801_ADMeanFused_WithTiles_Trans.tif
Traceback (most recent call last):
  File "d:\09_Code\Gis_Script\05_SAM\º‡Ã˝SAM.py", line 57, in process_file
    sam.predict(boxes=boxes, point_crs="EPSG:4326", output=output_path, dtype="uint8")
  File "D:\Wrz\anaconda\envs\GEE\Lib\site-packages\samgeo\samgeo.py", line 581, in predict
    if isinstance(coords[0], int):
                  ~~~~~~^^^
TypeError: 'NoneType' object is not subscriptable

Predict error file = D:\Dataset_and_Demo\2015-09-15_to_2015-11-28\01817_ADMeanFused_WithTiles_Trans.tif
Traceback (most recent call last):
  File "d:\09_Code\Gis_Script\05_SAM\º‡Ã˝SAM.py", line 57, in process_file
    sam.predict(boxes=boxes, point_crs="EPSG:4326", output=output_path, dtype="uint8")
  File "D:\Wrz\anaconda\envs\GEE\Lib\site-packages\samgeo\samgeo.py", line 581, in predict
    if isinstance(coords[0], int):
                  ~~~~~~^^^
TypeError: 'NoneType' object is not subscriptable

Predict error file = D:\Dataset_and_Demo\2015-09-15_to_2015-11-28\01819_ADMeanFused_WithTiles_Trans.tif
Traceback (most recent call last):
  File "d:\09_Code\Gis_Script\05_SAM\º‡Ã˝SAM.py", line 57, in process_file
    sam.predict(boxes=boxes, point_crs="EPSG:4326", output=output_path, dtype="uint8")
  File "D:\Wrz\anaconda\envs\GEE\Lib\site-packages\samgeo\samgeo.py", line 581, in predict
    if isinstance(coords[0], int):
                  ~~~~~~^^^
TypeError: 'NoneType' object is not subscriptable

Predict error file = D:\Dataset_and_Demo\2015-09-15_to_2015-11-28\01827_ADMeanFused_WithTiles_Trans.tif
Traceback (most recent call last):
  File "d:\09_Code\Gis_Script\05_SAM\º‡Ã˝SAM.py", line 57, in process_file
    sam.predict(boxes=boxes, point_crs="EPSG:4326", output=output_path, dtype="uint8")
  File "D:\Wrz\anaconda\envs\GEE\Lib\site-packages\samgeo\samgeo.py", line 581, in predict
    if isinstance(coords[0], int):
                  ~~~~~~^^^
TypeError: 'NoneType' object is not subscriptable

Predict error file = D:\Dataset_and_Demo\2015-09-15_to_2015-11-28\01862_ADMeanFused_WithTiles_Trans.tif
Traceback (most recent call last):
  File "d:\09_Code\Gis_Script\05_SAM\º‡Ã˝SAM.py", line 57, in process_file
    sam.predict(boxes=boxes, point_crs="EPSG:4326", output=output_path, dtype="uint8")
  File "D:\Wrz\anaconda\envs\GEE\Lib\site-packages\samgeo\samgeo.py", line 581, in predict
    if isinstance(coords[0], int):
                  ~~~~~~^^^
TypeError: 'NoneType' object is not subscriptable

Predict error file = D:\Dataset_and_Demo\2015-02-25_to_2015-05-31\04657_ADMeanFused_Trans.tif
Traceback (most recent call last):
  File "d:\09_Code\Gis_Script\05_SAM\º‡Ã˝SAM.py", line 50, in process_file
    AOI_Bound_Info = json.load(f)
                     ^^^^^^^^^^^^
  File "D:\Wrz\anaconda\envs\GEE\Lib\json\__init__.py", line 293, in load
    return loads(fp.read(),
           ^^^^^^^^^^^^^^^^
  File "D:\Wrz\anaconda\envs\GEE\Lib\json\__init__.py", line 346, in loads
    return _default_decoder.decode(s)
           ^^^^^^^^^^^^^^^^^^^^^^^^^^
  File "D:\Wrz\anaconda\envs\GEE\Lib\json\decoder.py", line 337, in decode
    obj, end = self.raw_decode(s, idx=_w(s, 0).end())
               ^^^^^^^^^^^^^^^^^^^^^^^^^^^^^^^^^^^^^^
  File "D:\Wrz\anaconda\envs\GEE\Lib\json\decoder.py", line 355, in raw_decode
    raise JSONDecodeError("Expecting value", s, err.value) from None
json.decoder.JSONDecodeError: Expecting value: line 1 column 1 (char 0)

Predict error file = D:\Dataset_and_Demo\2015-05-31_to_2015-09-15\00304_ADMeanFused_Trans.tif
Traceback (most recent call last):
  File "d:\09_Code\Gis_Script\05_SAM\º‡Ã˝SAM.py", line 50, in process_file
    AOI_Bound_Info = json.load(f)
                     ^^^^^^^^^^^^
  File "D:\Wrz\anaconda\envs\GEE\Lib\json\__init__.py", line 293, in load
    return loads(fp.read(),
           ^^^^^^^^^^^^^^^^
  File "D:\Wrz\anaconda\envs\GEE\Lib\json\__init__.py", line 346, in loads
    return _default_decoder.decode(s)
           ^^^^^^^^^^^^^^^^^^^^^^^^^^
  File "D:\Wrz\anaconda\envs\GEE\Lib\json\decoder.py", line 337, in decode
    obj, end = self.raw_decode(s, idx=_w(s, 0).end())
               ^^^^^^^^^^^^^^^^^^^^^^^^^^^^^^^^^^^^^^
  File "D:\Wrz\anaconda\envs\GEE\Lib\json\decoder.py", line 355, in raw_decode
    raise JSONDecodeError("Expecting value", s, err.value) from None
json.decoder.JSONDecodeError: Expecting value: line 1 column 1 (char 0)

Predict error file = D:\Dataset_and_Demo\2015-05-31_to_2015-09-15\00306_ADMeanFused_Trans.tif
Traceback (most recent call last):
  File "d:\09_Code\Gis_Script\05_SAM\º‡Ã˝SAM.py", line 50, in process_file
    AOI_Bound_Info = json.load(f)
                     ^^^^^^^^^^^^
  File "D:\Wrz\anaconda\envs\GEE\Lib\json\__init__.py", line 293, in load
    return loads(fp.read(),
           ^^^^^^^^^^^^^^^^
  File "D:\Wrz\anaconda\envs\GEE\Lib\json\__init__.py", line 346, in loads
    return _default_decoder.decode(s)
           ^^^^^^^^^^^^^^^^^^^^^^^^^^
  File "D:\Wrz\anaconda\envs\GEE\Lib\json\decoder.py", line 337, in decode
    obj, end = self.raw_decode(s, idx=_w(s, 0).end())
               ^^^^^^^^^^^^^^^^^^^^^^^^^^^^^^^^^^^^^^
  File "D:\Wrz\anaconda\envs\GEE\Lib\json\decoder.py", line 355, in raw_decode
    raise JSONDecodeError("Expecting value", s, err.value) from None
json.decoder.JSONDecodeError: Expecting value: line 1 column 1 (char 0)

Predict error file = D:\Dataset_and_Demo\2015-09-15_to_2015-11-28\01791_ADMeanFused_Trans.tif
Traceback (most recent call last):
  File "d:\09_Code\Gis_Script\05_SAM\º‡Ã˝SAM.py", line 50, in process_file
    AOI_Bound_Info = json.load(f)
                     ^^^^^^^^^^^^
  File "D:\Wrz\anaconda\envs\GEE\Lib\json\__init__.py", line 293, in load
    return loads(fp.read(),
           ^^^^^^^^^^^^^^^^
  File "D:\Wrz\anaconda\envs\GEE\Lib\json\__init__.py", line 346, in loads
    return _default_decoder.decode(s)
           ^^^^^^^^^^^^^^^^^^^^^^^^^^
  File "D:\Wrz\anaconda\envs\GEE\Lib\json\decoder.py", line 337, in decode
    obj, end = self.raw_decode(s, idx=_w(s, 0).end())
               ^^^^^^^^^^^^^^^^^^^^^^^^^^^^^^^^^^^^^^
  File "D:\Wrz\anaconda\envs\GEE\Lib\json\decoder.py", line 355, in raw_decode
    raise JSONDecodeError("Expecting value", s, err.value) from None
json.decoder.JSONDecodeError: Expecting value: line 1 column 1 (char 0)

Predict error file = D:\Dataset_and_Demo\2015-09-15_to_2015-11-28\01801_ADMeanFused_WithTiles_Trans.tif
Traceback (most recent call last):
  File "d:\09_Code\Gis_Script\05_SAM\º‡Ã˝SAM.py", line 57, in process_file
    sam.predict(boxes=boxes, point_crs="EPSG:4326", output=output_path, dtype="uint8")
  File "D:\Wrz\anaconda\envs\GEE\Lib\site-packages\samgeo\samgeo.py", line 581, in predict
    if isinstance(coords[0], int):
                  ~~~~~~^^^
TypeError: 'NoneType' object is not subscriptable

Predict error file = D:\Dataset_and_Demo\2015-09-15_to_2015-11-28\01817_ADMeanFused_WithTiles_Trans.tif
Traceback (most recent call last):
  File "d:\09_Code\Gis_Script\05_SAM\º‡Ã˝SAM.py", line 57, in process_file
    sam.predict(boxes=boxes, point_crs="EPSG:4326", output=output_path, dtype="uint8")
  File "D:\Wrz\anaconda\envs\GEE\Lib\site-packages\samgeo\samgeo.py", line 581, in predict
    if isinstance(coords[0], int):
                  ~~~~~~^^^
TypeError: 'NoneType' object is not subscriptable

Predict error file = D:\Dataset_and_Demo\2015-09-15_to_2015-11-28\01819_ADMeanFused_WithTiles_Trans.tif
Traceback (most recent call last):
  File "d:\09_Code\Gis_Script\05_SAM\º‡Ã˝SAM.py", line 57, in process_file
    sam.predict(boxes=boxes, point_crs="EPSG:4326", output=output_path, dtype="uint8")
  File "D:\Wrz\anaconda\envs\GEE\Lib\site-packages\samgeo\samgeo.py", line 581, in predict
    if isinstance(coords[0], int):
                  ~~~~~~^^^
TypeError: 'NoneType' object is not subscriptable

Predict error file = D:\Dataset_and_Demo\2015-09-15_to_2015-11-28\01827_ADMeanFused_WithTiles_Trans.tif
Traceback (most recent call last):
  File "d:\09_Code\Gis_Script\05_SAM\º‡Ã˝SAM.py", line 57, in process_file
    sam.predict(boxes=boxes, point_crs="EPSG:4326", output=output_path, dtype="uint8")
  File "D:\Wrz\anaconda\envs\GEE\Lib\site-packages\samgeo\samgeo.py", line 581, in predict
    if isinstance(coords[0], int):
                  ~~~~~~^^^
TypeError: 'NoneType' object is not subscriptable

Predict error file = D:\Dataset_and_Demo\2015-09-15_to_2015-11-28\01862_ADMeanFused_WithTiles_Trans.tif
Traceback (most recent call last):
  File "d:\09_Code\Gis_Script\05_SAM\º‡Ã˝SAM.py", line 57, in process_file
    sam.predict(boxes=boxes, point_crs="EPSG:4326", output=output_path, dtype="uint8")
  File "D:\Wrz\anaconda\envs\GEE\Lib\site-packages\samgeo\samgeo.py", line 581, in predict
    if isinstance(coords[0], int):
                  ~~~~~~^^^
TypeError: 'NoneType' object is not subscriptable

Predict error file = D:\Dataset_and_Demo\2015-02-25_to_2015-05-31\04657_ADMeanFused_Trans.tif
Traceback (most recent call last):
  File "d:\09_Code\Gis_Script\05_SAM\º‡Ã˝SAM.py", line 50, in process_file
    AOI_Bound_Info = json.load(f)
                     ^^^^^^^^^^^^
  File "D:\Wrz\anaconda\envs\GEE\Lib\json\__init__.py", line 293, in load
    return loads(fp.read(),
           ^^^^^^^^^^^^^^^^
  File "D:\Wrz\anaconda\envs\GEE\Lib\json\__init__.py", line 346, in loads
    return _default_decoder.decode(s)
           ^^^^^^^^^^^^^^^^^^^^^^^^^^
  File "D:\Wrz\anaconda\envs\GEE\Lib\json\decoder.py", line 337, in decode
    obj, end = self.raw_decode(s, idx=_w(s, 0).end())
               ^^^^^^^^^^^^^^^^^^^^^^^^^^^^^^^^^^^^^^
  File "D:\Wrz\anaconda\envs\GEE\Lib\json\decoder.py", line 355, in raw_decode
    raise JSONDecodeError("Expecting value", s, err.value) from None
json.decoder.JSONDecodeError: Expecting value: line 1 column 1 (char 0)

Predict error file = D:\Dataset_and_Demo\2015-05-31_to_2015-09-15\00304_ADMeanFused_Trans.tif
Traceback (most recent call last):
  File "d:\09_Code\Gis_Script\05_SAM\º‡Ã˝SAM.py", line 50, in process_file
    AOI_Bound_Info = json.load(f)
                     ^^^^^^^^^^^^
  File "D:\Wrz\anaconda\envs\GEE\Lib\json\__init__.py", line 293, in load
    return loads(fp.read(),
           ^^^^^^^^^^^^^^^^
  File "D:\Wrz\anaconda\envs\GEE\Lib\json\__init__.py", line 346, in loads
    return _default_decoder.decode(s)
           ^^^^^^^^^^^^^^^^^^^^^^^^^^
  File "D:\Wrz\anaconda\envs\GEE\Lib\json\decoder.py", line 337, in decode
    obj, end = self.raw_decode(s, idx=_w(s, 0).end())
               ^^^^^^^^^^^^^^^^^^^^^^^^^^^^^^^^^^^^^^
  File "D:\Wrz\anaconda\envs\GEE\Lib\json\decoder.py", line 355, in raw_decode
    raise JSONDecodeError("Expecting value", s, err.value) from None
json.decoder.JSONDecodeError: Expecting value: line 1 column 1 (char 0)

Predict error file = D:\Dataset_and_Demo\2015-05-31_to_2015-09-15\00306_ADMeanFused_Trans.tif
Traceback (most recent call last):
  File "d:\09_Code\Gis_Script\05_SAM\º‡Ã˝SAM.py", line 50, in process_file
    AOI_Bound_Info = json.load(f)
                     ^^^^^^^^^^^^
  File "D:\Wrz\anaconda\envs\GEE\Lib\json\__init__.py", line 293, in load
    return loads(fp.read(),
           ^^^^^^^^^^^^^^^^
  File "D:\Wrz\anaconda\envs\GEE\Lib\json\__init__.py", line 346, in loads
    return _default_decoder.decode(s)
           ^^^^^^^^^^^^^^^^^^^^^^^^^^
  File "D:\Wrz\anaconda\envs\GEE\Lib\json\decoder.py", line 337, in decode
    obj, end = self.raw_decode(s, idx=_w(s, 0).end())
               ^^^^^^^^^^^^^^^^^^^^^^^^^^^^^^^^^^^^^^
  File "D:\Wrz\anaconda\envs\GEE\Lib\json\decoder.py", line 355, in raw_decode
    raise JSONDecodeError("Expecting value", s, err.value) from None
json.decoder.JSONDecodeError: Expecting value: line 1 column 1 (char 0)

Predict error file = D:\Dataset_and_Demo\2015-09-15_to_2015-11-28\01791_ADMeanFused_Trans.tif
Traceback (most recent call last):
  File "d:\09_Code\Gis_Script\05_SAM\º‡Ã˝SAM.py", line 50, in process_file
    AOI_Bound_Info = json.load(f)
                     ^^^^^^^^^^^^
  File "D:\Wrz\anaconda\envs\GEE\Lib\json\__init__.py", line 293, in load
    return loads(fp.read(),
           ^^^^^^^^^^^^^^^^
  File "D:\Wrz\anaconda\envs\GEE\Lib\json\__init__.py", line 346, in loads
    return _default_decoder.decode(s)
           ^^^^^^^^^^^^^^^^^^^^^^^^^^
  File "D:\Wrz\anaconda\envs\GEE\Lib\json\decoder.py", line 337, in decode
    obj, end = self.raw_decode(s, idx=_w(s, 0).end())
               ^^^^^^^^^^^^^^^^^^^^^^^^^^^^^^^^^^^^^^
  File "D:\Wrz\anaconda\envs\GEE\Lib\json\decoder.py", line 355, in raw_decode
    raise JSONDecodeError("Expecting value", s, err.value) from None
json.decoder.JSONDecodeError: Expecting value: line 1 column 1 (char 0)

Predict error file = D:\Dataset_and_Demo\2015-09-15_to_2015-11-28\01801_ADMeanFused_WithTiles_Trans.tif
Traceback (most recent call last):
  File "d:\09_Code\Gis_Script\05_SAM\º‡Ã˝SAM.py", line 57, in process_file
    sam.predict(boxes=boxes, point_crs="EPSG:4326", output=output_path, dtype="uint8")
  File "D:\Wrz\anaconda\envs\GEE\Lib\site-packages\samgeo\samgeo.py", line 581, in predict
    if isinstance(coords[0], int):
                  ~~~~~~^^^
TypeError: 'NoneType' object is not subscriptable

Predict error file = D:\Dataset_and_Demo\2015-09-15_to_2015-11-28\01817_ADMeanFused_WithTiles_Trans.tif
Traceback (most recent call last):
  File "d:\09_Code\Gis_Script\05_SAM\º‡Ã˝SAM.py", line 57, in process_file
    sam.predict(boxes=boxes, point_crs="EPSG:4326", output=output_path, dtype="uint8")
  File "D:\Wrz\anaconda\envs\GEE\Lib\site-packages\samgeo\samgeo.py", line 581, in predict
    if isinstance(coords[0], int):
                  ~~~~~~^^^
TypeError: 'NoneType' object is not subscriptable

Predict error file = D:\Dataset_and_Demo\2015-09-15_to_2015-11-28\01819_ADMeanFused_WithTiles_Trans.tif
Traceback (most recent call last):
  File "d:\09_Code\Gis_Script\05_SAM\º‡Ã˝SAM.py", line 57, in process_file
    sam.predict(boxes=boxes, point_crs="EPSG:4326", output=output_path, dtype="uint8")
  File "D:\Wrz\anaconda\envs\GEE\Lib\site-packages\samgeo\samgeo.py", line 581, in predict
    if isinstance(coords[0], int):
                  ~~~~~~^^^
TypeError: 'NoneType' object is not subscriptable

Predict error file = D:\Dataset_and_Demo\2015-09-15_to_2015-11-28\01827_ADMeanFused_WithTiles_Trans.tif
Traceback (most recent call last):
  File "d:\09_Code\Gis_Script\05_SAM\º‡Ã˝SAM.py", line 57, in process_file
    sam.predict(boxes=boxes, point_crs="EPSG:4326", output=output_path, dtype="uint8")
  File "D:\Wrz\anaconda\envs\GEE\Lib\site-packages\samgeo\samgeo.py", line 581, in predict
    if isinstance(coords[0], int):
                  ~~~~~~^^^
TypeError: 'NoneType' object is not subscriptable

Predict error file = D:\Dataset_and_Demo\2015-09-15_to_2015-11-28\01862_ADMeanFused_WithTiles_Trans.tif
Traceback (most recent call last):
  File "d:\09_Code\Gis_Script\05_SAM\º‡Ã˝SAM.py", line 57, in process_file
    sam.predict(boxes=boxes, point_crs="EPSG:4326", output=output_path, dtype="uint8")
  File "D:\Wrz\anaconda\envs\GEE\Lib\site-packages\samgeo\samgeo.py", line 581, in predict
    if isinstance(coords[0], int):
                  ~~~~~~^^^
TypeError: 'NoneType' object is not subscriptable

Predict error file = D:\Dataset_and_Demo\2015-02-25_to_2015-05-31\04657_ADMeanFused_Trans.tif
Traceback (most recent call last):
  File "d:\09_Code\Gis_Script\05_SAM\º‡Ã˝SAM.py", line 50, in process_file
    AOI_Bound_Info = json.load(f)
                     ^^^^^^^^^^^^
  File "D:\Wrz\anaconda\envs\GEE\Lib\json\__init__.py", line 293, in load
    return loads(fp.read(),
           ^^^^^^^^^^^^^^^^
  File "D:\Wrz\anaconda\envs\GEE\Lib\json\__init__.py", line 346, in loads
    return _default_decoder.decode(s)
           ^^^^^^^^^^^^^^^^^^^^^^^^^^
  File "D:\Wrz\anaconda\envs\GEE\Lib\json\decoder.py", line 337, in decode
    obj, end = self.raw_decode(s, idx=_w(s, 0).end())
               ^^^^^^^^^^^^^^^^^^^^^^^^^^^^^^^^^^^^^^
  File "D:\Wrz\anaconda\envs\GEE\Lib\json\decoder.py", line 355, in raw_decode
    raise JSONDecodeError("Expecting value", s, err.value) from None
json.decoder.JSONDecodeError: Expecting value: line 1 column 1 (char 0)

Predict error file = D:\Dataset_and_Demo\2015-05-31_to_2015-09-15\00304_ADMeanFused_Trans.tif
Traceback (most recent call last):
  File "d:\09_Code\Gis_Script\05_SAM\º‡Ã˝SAM.py", line 50, in process_file
    AOI_Bound_Info = json.load(f)
                     ^^^^^^^^^^^^
  File "D:\Wrz\anaconda\envs\GEE\Lib\json\__init__.py", line 293, in load
    return loads(fp.read(),
           ^^^^^^^^^^^^^^^^
  File "D:\Wrz\anaconda\envs\GEE\Lib\json\__init__.py", line 346, in loads
    return _default_decoder.decode(s)
           ^^^^^^^^^^^^^^^^^^^^^^^^^^
  File "D:\Wrz\anaconda\envs\GEE\Lib\json\decoder.py", line 337, in decode
    obj, end = self.raw_decode(s, idx=_w(s, 0).end())
               ^^^^^^^^^^^^^^^^^^^^^^^^^^^^^^^^^^^^^^
  File "D:\Wrz\anaconda\envs\GEE\Lib\json\decoder.py", line 355, in raw_decode
    raise JSONDecodeError("Expecting value", s, err.value) from None
json.decoder.JSONDecodeError: Expecting value: line 1 column 1 (char 0)

Predict error file = D:\Dataset_and_Demo\2015-05-31_to_2015-09-15\00306_ADMeanFused_Trans.tif
Traceback (most recent call last):
  File "d:\09_Code\Gis_Script\05_SAM\º‡Ã˝SAM.py", line 50, in process_file
    AOI_Bound_Info = json.load(f)
                     ^^^^^^^^^^^^
  File "D:\Wrz\anaconda\envs\GEE\Lib\json\__init__.py", line 293, in load
    return loads(fp.read(),
           ^^^^^^^^^^^^^^^^
  File "D:\Wrz\anaconda\envs\GEE\Lib\json\__init__.py", line 346, in loads
    return _default_decoder.decode(s)
           ^^^^^^^^^^^^^^^^^^^^^^^^^^
  File "D:\Wrz\anaconda\envs\GEE\Lib\json\decoder.py", line 337, in decode
    obj, end = self.raw_decode(s, idx=_w(s, 0).end())
               ^^^^^^^^^^^^^^^^^^^^^^^^^^^^^^^^^^^^^^
  File "D:\Wrz\anaconda\envs\GEE\Lib\json\decoder.py", line 355, in raw_decode
    raise JSONDecodeError("Expecting value", s, err.value) from None
json.decoder.JSONDecodeError: Expecting value: line 1 column 1 (char 0)

Predict error file = D:\Dataset_and_Demo\2015-09-15_to_2015-11-28\01791_ADMeanFused_Trans.tif
Traceback (most recent call last):
  File "d:\09_Code\Gis_Script\05_SAM\º‡Ã˝SAM.py", line 50, in process_file
    AOI_Bound_Info = json.load(f)
                     ^^^^^^^^^^^^
  File "D:\Wrz\anaconda\envs\GEE\Lib\json\__init__.py", line 293, in load
    return loads(fp.read(),
           ^^^^^^^^^^^^^^^^
  File "D:\Wrz\anaconda\envs\GEE\Lib\json\__init__.py", line 346, in loads
    return _default_decoder.decode(s)
           ^^^^^^^^^^^^^^^^^^^^^^^^^^
  File "D:\Wrz\anaconda\envs\GEE\Lib\json\decoder.py", line 337, in decode
    obj, end = self.raw_decode(s, idx=_w(s, 0).end())
               ^^^^^^^^^^^^^^^^^^^^^^^^^^^^^^^^^^^^^^
  File "D:\Wrz\anaconda\envs\GEE\Lib\json\decoder.py", line 355, in raw_decode
    raise JSONDecodeError("Expecting value", s, err.value) from None
json.decoder.JSONDecodeError: Expecting value: line 1 column 1 (char 0)

Predict error file = D:\Dataset_and_Demo\2015-09-15_to_2015-11-28\01801_ADMeanFused_WithTiles_Trans.tif
Traceback (most recent call last):
  File "d:\09_Code\Gis_Script\05_SAM\º‡Ã˝SAM.py", line 57, in process_file
    sam.predict(boxes=boxes, point_crs="EPSG:4326", output=output_path, dtype="uint8")
  File "D:\Wrz\anaconda\envs\GEE\Lib\site-packages\samgeo\samgeo.py", line 581, in predict
    if isinstance(coords[0], int):
                  ~~~~~~^^^
TypeError: 'NoneType' object is not subscriptable

Predict error file = D:\Dataset_and_Demo\2015-09-15_to_2015-11-28\01817_ADMeanFused_WithTiles_Trans.tif
Traceback (most recent call last):
  File "d:\09_Code\Gis_Script\05_SAM\º‡Ã˝SAM.py", line 57, in process_file
    sam.predict(boxes=boxes, point_crs="EPSG:4326", output=output_path, dtype="uint8")
  File "D:\Wrz\anaconda\envs\GEE\Lib\site-packages\samgeo\samgeo.py", line 581, in predict
    if isinstance(coords[0], int):
                  ~~~~~~^^^
TypeError: 'NoneType' object is not subscriptable

Predict error file = D:\Dataset_and_Demo\2015-09-15_to_2015-11-28\01819_ADMeanFused_WithTiles_Trans.tif
Traceback (most recent call last):
  File "d:\09_Code\Gis_Script\05_SAM\º‡Ã˝SAM.py", line 57, in process_file
    sam.predict(boxes=boxes, point_crs="EPSG:4326", output=output_path, dtype="uint8")
  File "D:\Wrz\anaconda\envs\GEE\Lib\site-packages\samgeo\samgeo.py", line 581, in predict
    if isinstance(coords[0], int):
                  ~~~~~~^^^
TypeError: 'NoneType' object is not subscriptable

Predict error file = D:\Dataset_and_Demo\2015-09-15_to_2015-11-28\01827_ADMeanFused_WithTiles_Trans.tif
Traceback (most recent call last):
  File "d:\09_Code\Gis_Script\05_SAM\º‡Ã˝SAM.py", line 57, in process_file
    sam.predict(boxes=boxes, point_crs="EPSG:4326", output=output_path, dtype="uint8")
  File "D:\Wrz\anaconda\envs\GEE\Lib\site-packages\samgeo\samgeo.py", line 581, in predict
    if isinstance(coords[0], int):
                  ~~~~~~^^^
TypeError: 'NoneType' object is not subscriptable

Predict error file = D:\Dataset_and_Demo\2015-09-15_to_2015-11-28\01862_ADMeanFused_WithTiles_Trans.tif
Traceback (most recent call last):
  File "d:\09_Code\Gis_Script\05_SAM\º‡Ã˝SAM.py", line 57, in process_file
    sam.predict(boxes=boxes, point_crs="EPSG:4326", output=output_path, dtype="uint8")
  File "D:\Wrz\anaconda\envs\GEE\Lib\site-packages\samgeo\samgeo.py", line 581, in predict
    if isinstance(coords[0], int):
                  ~~~~~~^^^
TypeError: 'NoneType' object is not subscriptable

Predict error file = D:\Dataset_and_Demo\2017-05-31_to_2017-09-15\00234_ADMeanFused_WithTiles_Trans.tif
Traceback (most recent call last):
  File "d:\09_Code\Gis_Script\05_SAM\º‡Ã˝SAM.py", line 57, in process_file
    sam.predict(boxes=boxes, point_crs="EPSG:4326", output=output_path, dtype="uint8")
  File "D:\Wrz\anaconda\envs\GEE\Lib\site-packages\samgeo\samgeo.py", line 581, in predict
    if isinstance(coords[0], int):
                  ~~~~~~^^^
TypeError: 'NoneType' object is not subscriptable

Predict error file = D:\Dataset_and_Demo\2017-05-31_to_2017-09-15\00235_ADMeanFused_WithTiles_Trans.tif
Traceback (most recent call last):
  File "d:\09_Code\Gis_Script\05_SAM\º‡Ã˝SAM.py", line 57, in process_file
    sam.predict(boxes=boxes, point_crs="EPSG:4326", output=output_path, dtype="uint8")
  File "D:\Wrz\anaconda\envs\GEE\Lib\site-packages\samgeo\samgeo.py", line 581, in predict
    if isinstance(coords[0], int):
                  ~~~~~~^^^
TypeError: 'NoneType' object is not subscriptable

Predict error file = D:\Dataset_and_Demo\2017-05-31_to_2017-09-15\00240_ADMeanFused_WithTiles_Trans.tif
Traceback (most recent call last):
  File "d:\09_Code\Gis_Script\05_SAM\º‡Ã˝SAM.py", line 57, in process_file
    sam.predict(boxes=boxes, point_crs="EPSG:4326", output=output_path, dtype="uint8")
  File "D:\Wrz\anaconda\envs\GEE\Lib\site-packages\samgeo\samgeo.py", line 581, in predict
    if isinstance(coords[0], int):
                  ~~~~~~^^^
TypeError: 'NoneType' object is not subscriptable

Predict error file = D:\Dataset_and_Demo\2017-05-31_to_2017-09-15\00261_ADMeanFused_WithTiles_Trans.tif
Traceback (most recent call last):
  File "d:\09_Code\Gis_Script\05_SAM\º‡Ã˝SAM.py", line 57, in process_file
    sam.predict(boxes=boxes, point_crs="EPSG:4326", output=output_path, dtype="uint8")
  File "D:\Wrz\anaconda\envs\GEE\Lib\site-packages\samgeo\samgeo.py", line 581, in predict
    if isinstance(coords[0], int):
                  ~~~~~~^^^
TypeError: 'NoneType' object is not subscriptable

Predict error file = D:\Dataset_and_Demo\2017-05-31_to_2017-09-15\00263_ADMeanFused_WithTiles_Trans.tif
Traceback (most recent call last):
  File "d:\09_Code\Gis_Script\05_SAM\º‡Ã˝SAM.py", line 57, in process_file
    sam.predict(boxes=boxes, point_crs="EPSG:4326", output=output_path, dtype="uint8")
  File "D:\Wrz\anaconda\envs\GEE\Lib\site-packages\samgeo\samgeo.py", line 581, in predict
    if isinstance(coords[0], int):
                  ~~~~~~^^^
TypeError: 'NoneType' object is not subscriptable

Predict error file = D:\Dataset_and_Demo\2017-05-31_to_2017-09-15\00264_ADMeanFused_WithTiles_Trans.tif
Traceback (most recent call last):
  File "d:\09_Code\Gis_Script\05_SAM\º‡Ã˝SAM.py", line 57, in process_file
    sam.predict(boxes=boxes, point_crs="EPSG:4326", output=output_path, dtype="uint8")
  File "D:\Wrz\anaconda\envs\GEE\Lib\site-packages\samgeo\samgeo.py", line 581, in predict
    if isinstance(coords[0], int):
                  ~~~~~~^^^
TypeError: 'NoneType' object is not subscriptable

Predict error file = D:\Dataset_and_Demo\2017-05-31_to_2017-09-15\00269_ADMeanFused_WithTiles_Trans.tif
Traceback (most recent call last):
  File "d:\09_Code\Gis_Script\05_SAM\º‡Ã˝SAM.py", line 57, in process_file
    sam.predict(boxes=boxes, point_crs="EPSG:4326", output=output_path, dtype="uint8")
  File "D:\Wrz\anaconda\envs\GEE\Lib\site-packages\samgeo\samgeo.py", line 581, in predict
    if isinstance(coords[0], int):
                  ~~~~~~^^^
TypeError: 'NoneType' object is not subscriptable

Predict error file = D:\Dataset_and_Demo\2017-05-31_to_2017-09-15\00357_ADMeanFused_WithTiles_Trans.tif
Traceback (most recent call last):
  File "d:\09_Code\Gis_Script\05_SAM\º‡Ã˝SAM.py", line 57, in process_file
    sam.predict(boxes=boxes, point_crs="EPSG:4326", output=output_path, dtype="uint8")
  File "D:\Wrz\anaconda\envs\GEE\Lib\site-packages\samgeo\samgeo.py", line 581, in predict
    if isinstance(coords[0], int):
                  ~~~~~~^^^
TypeError: 'NoneType' object is not subscriptable

Predict error file = D:\Dataset_and_Demo\2015-02-25_to_2015-05-31\04657_ADMeanFused_Trans.tif
Traceback (most recent call last):
  File "d:\09_Code\Gis_Script\05_SAM\º‡Ã˝SAM.py", line 50, in process_file
    AOI_Bound_Info = json.load(f)
                     ^^^^^^^^^^^^
  File "D:\Wrz\anaconda\envs\GEE\Lib\json\__init__.py", line 293, in load
    return loads(fp.read(),
           ^^^^^^^^^^^^^^^^
  File "D:\Wrz\anaconda\envs\GEE\Lib\json\__init__.py", line 346, in loads
    return _default_decoder.decode(s)
           ^^^^^^^^^^^^^^^^^^^^^^^^^^
  File "D:\Wrz\anaconda\envs\GEE\Lib\json\decoder.py", line 337, in decode
    obj, end = self.raw_decode(s, idx=_w(s, 0).end())
               ^^^^^^^^^^^^^^^^^^^^^^^^^^^^^^^^^^^^^^
  File "D:\Wrz\anaconda\envs\GEE\Lib\json\decoder.py", line 355, in raw_decode
    raise JSONDecodeError("Expecting value", s, err.value) from None
json.decoder.JSONDecodeError: Expecting value: line 1 column 1 (char 0)

Predict error file = D:\Dataset_and_Demo\2015-05-31_to_2015-09-15\00304_ADMeanFused_Trans.tif
Traceback (most recent call last):
  File "d:\09_Code\Gis_Script\05_SAM\º‡Ã˝SAM.py", line 50, in process_file
    AOI_Bound_Info = json.load(f)
                     ^^^^^^^^^^^^
  File "D:\Wrz\anaconda\envs\GEE\Lib\json\__init__.py", line 293, in load
    return loads(fp.read(),
           ^^^^^^^^^^^^^^^^
  File "D:\Wrz\anaconda\envs\GEE\Lib\json\__init__.py", line 346, in loads
    return _default_decoder.decode(s)
           ^^^^^^^^^^^^^^^^^^^^^^^^^^
  File "D:\Wrz\anaconda\envs\GEE\Lib\json\decoder.py", line 337, in decode
    obj, end = self.raw_decode(s, idx=_w(s, 0).end())
               ^^^^^^^^^^^^^^^^^^^^^^^^^^^^^^^^^^^^^^
  File "D:\Wrz\anaconda\envs\GEE\Lib\json\decoder.py", line 355, in raw_decode
    raise JSONDecodeError("Expecting value", s, err.value) from None
json.decoder.JSONDecodeError: Expecting value: line 1 column 1 (char 0)

Predict error file = D:\Dataset_and_Demo\2015-05-31_to_2015-09-15\00306_ADMeanFused_Trans.tif
Traceback (most recent call last):
  File "d:\09_Code\Gis_Script\05_SAM\º‡Ã˝SAM.py", line 50, in process_file
    AOI_Bound_Info = json.load(f)
                     ^^^^^^^^^^^^
  File "D:\Wrz\anaconda\envs\GEE\Lib\json\__init__.py", line 293, in load
    return loads(fp.read(),
           ^^^^^^^^^^^^^^^^
  File "D:\Wrz\anaconda\envs\GEE\Lib\json\__init__.py", line 346, in loads
    return _default_decoder.decode(s)
           ^^^^^^^^^^^^^^^^^^^^^^^^^^
  File "D:\Wrz\anaconda\envs\GEE\Lib\json\decoder.py", line 337, in decode
    obj, end = self.raw_decode(s, idx=_w(s, 0).end())
               ^^^^^^^^^^^^^^^^^^^^^^^^^^^^^^^^^^^^^^
  File "D:\Wrz\anaconda\envs\GEE\Lib\json\decoder.py", line 355, in raw_decode
    raise JSONDecodeError("Expecting value", s, err.value) from None
json.decoder.JSONDecodeError: Expecting value: line 1 column 1 (char 0)

Predict error file = D:\Dataset_and_Demo\2015-09-15_to_2015-11-28\01791_ADMeanFused_Trans.tif
Traceback (most recent call last):
  File "d:\09_Code\Gis_Script\05_SAM\º‡Ã˝SAM.py", line 50, in process_file
    AOI_Bound_Info = json.load(f)
                     ^^^^^^^^^^^^
  File "D:\Wrz\anaconda\envs\GEE\Lib\json\__init__.py", line 293, in load
    return loads(fp.read(),
           ^^^^^^^^^^^^^^^^
  File "D:\Wrz\anaconda\envs\GEE\Lib\json\__init__.py", line 346, in loads
    return _default_decoder.decode(s)
           ^^^^^^^^^^^^^^^^^^^^^^^^^^
  File "D:\Wrz\anaconda\envs\GEE\Lib\json\decoder.py", line 337, in decode
    obj, end = self.raw_decode(s, idx=_w(s, 0).end())
               ^^^^^^^^^^^^^^^^^^^^^^^^^^^^^^^^^^^^^^
  File "D:\Wrz\anaconda\envs\GEE\Lib\json\decoder.py", line 355, in raw_decode
    raise JSONDecodeError("Expecting value", s, err.value) from None
json.decoder.JSONDecodeError: Expecting value: line 1 column 1 (char 0)

Predict error file = D:\Dataset_and_Demo\2015-09-15_to_2015-11-28\01801_ADMeanFused_WithTiles_Trans.tif
Traceback (most recent call last):
  File "d:\09_Code\Gis_Script\05_SAM\º‡Ã˝SAM.py", line 57, in process_file
    sam.predict(boxes=boxes, point_crs="EPSG:4326", output=output_path, dtype="uint8")
  File "D:\Wrz\anaconda\envs\GEE\Lib\site-packages\samgeo\samgeo.py", line 581, in predict
    if isinstance(coords[0], int):
                  ~~~~~~^^^
TypeError: 'NoneType' object is not subscriptable

Predict error file = D:\Dataset_and_Demo\2015-09-15_to_2015-11-28\01817_ADMeanFused_WithTiles_Trans.tif
Traceback (most recent call last):
  File "d:\09_Code\Gis_Script\05_SAM\º‡Ã˝SAM.py", line 57, in process_file
    sam.predict(boxes=boxes, point_crs="EPSG:4326", output=output_path, dtype="uint8")
  File "D:\Wrz\anaconda\envs\GEE\Lib\site-packages\samgeo\samgeo.py", line 581, in predict
    if isinstance(coords[0], int):
                  ~~~~~~^^^
TypeError: 'NoneType' object is not subscriptable

Predict error file = D:\Dataset_and_Demo\2015-09-15_to_2015-11-28\01819_ADMeanFused_WithTiles_Trans.tif
Traceback (most recent call last):
  File "d:\09_Code\Gis_Script\05_SAM\º‡Ã˝SAM.py", line 57, in process_file
    sam.predict(boxes=boxes, point_crs="EPSG:4326", output=output_path, dtype="uint8")
  File "D:\Wrz\anaconda\envs\GEE\Lib\site-packages\samgeo\samgeo.py", line 581, in predict
    if isinstance(coords[0], int):
                  ~~~~~~^^^
TypeError: 'NoneType' object is not subscriptable

Predict error file = D:\Dataset_and_Demo\2015-09-15_to_2015-11-28\01827_ADMeanFused_WithTiles_Trans.tif
Traceback (most recent call last):
  File "d:\09_Code\Gis_Script\05_SAM\º‡Ã˝SAM.py", line 57, in process_file
    sam.predict(boxes=boxes, point_crs="EPSG:4326", output=output_path, dtype="uint8")
  File "D:\Wrz\anaconda\envs\GEE\Lib\site-packages\samgeo\samgeo.py", line 581, in predict
    if isinstance(coords[0], int):
                  ~~~~~~^^^
TypeError: 'NoneType' object is not subscriptable

Predict error file = D:\Dataset_and_Demo\2015-09-15_to_2015-11-28\01862_ADMeanFused_WithTiles_Trans.tif
Traceback (most recent call last):
  File "d:\09_Code\Gis_Script\05_SAM\º‡Ã˝SAM.py", line 57, in process_file
    sam.predict(boxes=boxes, point_crs="EPSG:4326", output=output_path, dtype="uint8")
  File "D:\Wrz\anaconda\envs\GEE\Lib\site-packages\samgeo\samgeo.py", line 581, in predict
    if isinstance(coords[0], int):
                  ~~~~~~^^^
TypeError: 'NoneType' object is not subscriptable

Predict error file = D:\Dataset_and_Demo\2017-05-31_to_2017-09-15\00234_ADMeanFused_WithTiles_Trans.tif
Traceback (most recent call last):
  File "d:\09_Code\Gis_Script\05_SAM\º‡Ã˝SAM.py", line 57, in process_file
    sam.predict(boxes=boxes, point_crs="EPSG:4326", output=output_path, dtype="uint8")
  File "D:\Wrz\anaconda\envs\GEE\Lib\site-packages\samgeo\samgeo.py", line 581, in predict
    if isinstance(coords[0], int):
                  ~~~~~~^^^
TypeError: 'NoneType' object is not subscriptable

Predict error file = D:\Dataset_and_Demo\2017-05-31_to_2017-09-15\00235_ADMeanFused_WithTiles_Trans.tif
Traceback (most recent call last):
  File "d:\09_Code\Gis_Script\05_SAM\º‡Ã˝SAM.py", line 57, in process_file
    sam.predict(boxes=boxes, point_crs="EPSG:4326", output=output_path, dtype="uint8")
  File "D:\Wrz\anaconda\envs\GEE\Lib\site-packages\samgeo\samgeo.py", line 581, in predict
    if isinstance(coords[0], int):
                  ~~~~~~^^^
TypeError: 'NoneType' object is not subscriptable

Predict error file = D:\Dataset_and_Demo\2017-05-31_to_2017-09-15\00240_ADMeanFused_WithTiles_Trans.tif
Traceback (most recent call last):
  File "d:\09_Code\Gis_Script\05_SAM\º‡Ã˝SAM.py", line 57, in process_file
    sam.predict(boxes=boxes, point_crs="EPSG:4326", output=output_path, dtype="uint8")
  File "D:\Wrz\anaconda\envs\GEE\Lib\site-packages\samgeo\samgeo.py", line 581, in predict
    if isinstance(coords[0], int):
                  ~~~~~~^^^
TypeError: 'NoneType' object is not subscriptable

Predict error file = D:\Dataset_and_Demo\2017-05-31_to_2017-09-15\00261_ADMeanFused_WithTiles_Trans.tif
Traceback (most recent call last):
  File "d:\09_Code\Gis_Script\05_SAM\º‡Ã˝SAM.py", line 57, in process_file
    sam.predict(boxes=boxes, point_crs="EPSG:4326", output=output_path, dtype="uint8")
  File "D:\Wrz\anaconda\envs\GEE\Lib\site-packages\samgeo\samgeo.py", line 581, in predict
    if isinstance(coords[0], int):
                  ~~~~~~^^^
TypeError: 'NoneType' object is not subscriptable

Predict error file = D:\Dataset_and_Demo\2017-05-31_to_2017-09-15\00263_ADMeanFused_WithTiles_Trans.tif
Traceback (most recent call last):
  File "d:\09_Code\Gis_Script\05_SAM\º‡Ã˝SAM.py", line 57, in process_file
    sam.predict(boxes=boxes, point_crs="EPSG:4326", output=output_path, dtype="uint8")
  File "D:\Wrz\anaconda\envs\GEE\Lib\site-packages\samgeo\samgeo.py", line 581, in predict
    if isinstance(coords[0], int):
                  ~~~~~~^^^
TypeError: 'NoneType' object is not subscriptable

Predict error file = D:\Dataset_and_Demo\2017-05-31_to_2017-09-15\00264_ADMeanFused_WithTiles_Trans.tif
Traceback (most recent call last):
  File "d:\09_Code\Gis_Script\05_SAM\º‡Ã˝SAM.py", line 57, in process_file
    sam.predict(boxes=boxes, point_crs="EPSG:4326", output=output_path, dtype="uint8")
  File "D:\Wrz\anaconda\envs\GEE\Lib\site-packages\samgeo\samgeo.py", line 581, in predict
    if isinstance(coords[0], int):
                  ~~~~~~^^^
TypeError: 'NoneType' object is not subscriptable

Predict error file = D:\Dataset_and_Demo\2017-05-31_to_2017-09-15\00269_ADMeanFused_WithTiles_Trans.tif
Traceback (most recent call last):
  File "d:\09_Code\Gis_Script\05_SAM\º‡Ã˝SAM.py", line 57, in process_file
    sam.predict(boxes=boxes, point_crs="EPSG:4326", output=output_path, dtype="uint8")
  File "D:\Wrz\anaconda\envs\GEE\Lib\site-packages\samgeo\samgeo.py", line 581, in predict
    if isinstance(coords[0], int):
                  ~~~~~~^^^
TypeError: 'NoneType' object is not subscriptable

Predict error file = D:\Dataset_and_Demo\2017-05-31_to_2017-09-15\00357_ADMeanFused_WithTiles_Trans.tif
Traceback (most recent call last):
  File "d:\09_Code\Gis_Script\05_SAM\º‡Ã˝SAM.py", line 57, in process_file
    sam.predict(boxes=boxes, point_crs="EPSG:4326", output=output_path, dtype="uint8")
  File "D:\Wrz\anaconda\envs\GEE\Lib\site-packages\samgeo\samgeo.py", line 581, in predict
    if isinstance(coords[0], int):
                  ~~~~~~^^^
TypeError: 'NoneType' object is not subscriptable

Predict error file = D:\Dataset_and_Demo\2015-02-25_to_2015-05-31\04657_ADMeanFused_Trans.tif
Traceback (most recent call last):
  File "d:\09_Code\Gis_Script\05_SAM\º‡Ã˝SAM.py", line 50, in process_file
    AOI_Bound_Info = json.load(f)
                     ^^^^^^^^^^^^
  File "D:\Wrz\anaconda\envs\GEE\Lib\json\__init__.py", line 293, in load
    return loads(fp.read(),
           ^^^^^^^^^^^^^^^^
  File "D:\Wrz\anaconda\envs\GEE\Lib\json\__init__.py", line 346, in loads
    return _default_decoder.decode(s)
           ^^^^^^^^^^^^^^^^^^^^^^^^^^
  File "D:\Wrz\anaconda\envs\GEE\Lib\json\decoder.py", line 337, in decode
    obj, end = self.raw_decode(s, idx=_w(s, 0).end())
               ^^^^^^^^^^^^^^^^^^^^^^^^^^^^^^^^^^^^^^
  File "D:\Wrz\anaconda\envs\GEE\Lib\json\decoder.py", line 355, in raw_decode
    raise JSONDecodeError("Expecting value", s, err.value) from None
json.decoder.JSONDecodeError: Expecting value: line 1 column 1 (char 0)

Predict error file = D:\Dataset_and_Demo\2015-05-31_to_2015-09-15\00304_ADMeanFused_Trans.tif
Traceback (most recent call last):
  File "d:\09_Code\Gis_Script\05_SAM\º‡Ã˝SAM.py", line 50, in process_file
    AOI_Bound_Info = json.load(f)
                     ^^^^^^^^^^^^
  File "D:\Wrz\anaconda\envs\GEE\Lib\json\__init__.py", line 293, in load
    return loads(fp.read(),
           ^^^^^^^^^^^^^^^^
  File "D:\Wrz\anaconda\envs\GEE\Lib\json\__init__.py", line 346, in loads
    return _default_decoder.decode(s)
           ^^^^^^^^^^^^^^^^^^^^^^^^^^
  File "D:\Wrz\anaconda\envs\GEE\Lib\json\decoder.py", line 337, in decode
    obj, end = self.raw_decode(s, idx=_w(s, 0).end())
               ^^^^^^^^^^^^^^^^^^^^^^^^^^^^^^^^^^^^^^
  File "D:\Wrz\anaconda\envs\GEE\Lib\json\decoder.py", line 355, in raw_decode
    raise JSONDecodeError("Expecting value", s, err.value) from None
json.decoder.JSONDecodeError: Expecting value: line 1 column 1 (char 0)

Predict error file = D:\Dataset_and_Demo\2015-05-31_to_2015-09-15\00306_ADMeanFused_Trans.tif
Traceback (most recent call last):
  File "d:\09_Code\Gis_Script\05_SAM\º‡Ã˝SAM.py", line 50, in process_file
    AOI_Bound_Info = json.load(f)
                     ^^^^^^^^^^^^
  File "D:\Wrz\anaconda\envs\GEE\Lib\json\__init__.py", line 293, in load
    return loads(fp.read(),
           ^^^^^^^^^^^^^^^^
  File "D:\Wrz\anaconda\envs\GEE\Lib\json\__init__.py", line 346, in loads
    return _default_decoder.decode(s)
           ^^^^^^^^^^^^^^^^^^^^^^^^^^
  File "D:\Wrz\anaconda\envs\GEE\Lib\json\decoder.py", line 337, in decode
    obj, end = self.raw_decode(s, idx=_w(s, 0).end())
               ^^^^^^^^^^^^^^^^^^^^^^^^^^^^^^^^^^^^^^
  File "D:\Wrz\anaconda\envs\GEE\Lib\json\decoder.py", line 355, in raw_decode
    raise JSONDecodeError("Expecting value", s, err.value) from None
json.decoder.JSONDecodeError: Expecting value: line 1 column 1 (char 0)

Predict error file = D:\Dataset_and_Demo\2015-09-15_to_2015-11-28\01791_ADMeanFused_Trans.tif
Traceback (most recent call last):
  File "d:\09_Code\Gis_Script\05_SAM\º‡Ã˝SAM.py", line 50, in process_file
    AOI_Bound_Info = json.load(f)
                     ^^^^^^^^^^^^
  File "D:\Wrz\anaconda\envs\GEE\Lib\json\__init__.py", line 293, in load
    return loads(fp.read(),
           ^^^^^^^^^^^^^^^^
  File "D:\Wrz\anaconda\envs\GEE\Lib\json\__init__.py", line 346, in loads
    return _default_decoder.decode(s)
           ^^^^^^^^^^^^^^^^^^^^^^^^^^
  File "D:\Wrz\anaconda\envs\GEE\Lib\json\decoder.py", line 337, in decode
    obj, end = self.raw_decode(s, idx=_w(s, 0).end())
               ^^^^^^^^^^^^^^^^^^^^^^^^^^^^^^^^^^^^^^
  File "D:\Wrz\anaconda\envs\GEE\Lib\json\decoder.py", line 355, in raw_decode
    raise JSONDecodeError("Expecting value", s, err.value) from None
json.decoder.JSONDecodeError: Expecting value: line 1 column 1 (char 0)

Predict error file = D:\Dataset_and_Demo\2015-09-15_to_2015-11-28\01801_ADMeanFused_WithTiles_Trans.tif
Traceback (most recent call last):
  File "d:\09_Code\Gis_Script\05_SAM\º‡Ã˝SAM.py", line 57, in process_file
    sam.predict(boxes=boxes, point_crs="EPSG:4326", output=output_path, dtype="uint8")
  File "D:\Wrz\anaconda\envs\GEE\Lib\site-packages\samgeo\samgeo.py", line 581, in predict
    if isinstance(coords[0], int):
                  ~~~~~~^^^
TypeError: 'NoneType' object is not subscriptable

Predict error file = D:\Dataset_and_Demo\2015-09-15_to_2015-11-28\01817_ADMeanFused_WithTiles_Trans.tif
Traceback (most recent call last):
  File "d:\09_Code\Gis_Script\05_SAM\º‡Ã˝SAM.py", line 57, in process_file
    sam.predict(boxes=boxes, point_crs="EPSG:4326", output=output_path, dtype="uint8")
  File "D:\Wrz\anaconda\envs\GEE\Lib\site-packages\samgeo\samgeo.py", line 581, in predict
    if isinstance(coords[0], int):
                  ~~~~~~^^^
TypeError: 'NoneType' object is not subscriptable

Predict error file = D:\Dataset_and_Demo\2015-09-15_to_2015-11-28\01819_ADMeanFused_WithTiles_Trans.tif
Traceback (most recent call last):
  File "d:\09_Code\Gis_Script\05_SAM\º‡Ã˝SAM.py", line 57, in process_file
    sam.predict(boxes=boxes, point_crs="EPSG:4326", output=output_path, dtype="uint8")
  File "D:\Wrz\anaconda\envs\GEE\Lib\site-packages\samgeo\samgeo.py", line 581, in predict
    if isinstance(coords[0], int):
                  ~~~~~~^^^
TypeError: 'NoneType' object is not subscriptable

Predict error file = D:\Dataset_and_Demo\2015-09-15_to_2015-11-28\01827_ADMeanFused_WithTiles_Trans.tif
Traceback (most recent call last):
  File "d:\09_Code\Gis_Script\05_SAM\º‡Ã˝SAM.py", line 57, in process_file
    sam.predict(boxes=boxes, point_crs="EPSG:4326", output=output_path, dtype="uint8")
  File "D:\Wrz\anaconda\envs\GEE\Lib\site-packages\samgeo\samgeo.py", line 581, in predict
    if isinstance(coords[0], int):
                  ~~~~~~^^^
TypeError: 'NoneType' object is not subscriptable

Predict error file = D:\Dataset_and_Demo\2015-09-15_to_2015-11-28\01862_ADMeanFused_WithTiles_Trans.tif
Traceback (most recent call last):
  File "d:\09_Code\Gis_Script\05_SAM\º‡Ã˝SAM.py", line 57, in process_file
    sam.predict(boxes=boxes, point_crs="EPSG:4326", output=output_path, dtype="uint8")
  File "D:\Wrz\anaconda\envs\GEE\Lib\site-packages\samgeo\samgeo.py", line 581, in predict
    if isinstance(coords[0], int):
                  ~~~~~~^^^
TypeError: 'NoneType' object is not subscriptable

Predict error file = D:\Dataset_and_Demo\2017-05-31_to_2017-09-15\00234_ADMeanFused_WithTiles_Trans.tif
Traceback (most recent call last):
  File "d:\09_Code\Gis_Script\05_SAM\º‡Ã˝SAM.py", line 57, in process_file
    sam.predict(boxes=boxes, point_crs="EPSG:4326", output=output_path, dtype="uint8")
  File "D:\Wrz\anaconda\envs\GEE\Lib\site-packages\samgeo\samgeo.py", line 581, in predict
    if isinstance(coords[0], int):
                  ~~~~~~^^^
TypeError: 'NoneType' object is not subscriptable

Predict error file = D:\Dataset_and_Demo\2017-05-31_to_2017-09-15\00235_ADMeanFused_WithTiles_Trans.tif
Traceback (most recent call last):
  File "d:\09_Code\Gis_Script\05_SAM\º‡Ã˝SAM.py", line 57, in process_file
    sam.predict(boxes=boxes, point_crs="EPSG:4326", output=output_path, dtype="uint8")
  File "D:\Wrz\anaconda\envs\GEE\Lib\site-packages\samgeo\samgeo.py", line 581, in predict
    if isinstance(coords[0], int):
                  ~~~~~~^^^
TypeError: 'NoneType' object is not subscriptable

Predict error file = D:\Dataset_and_Demo\2017-05-31_to_2017-09-15\00240_ADMeanFused_WithTiles_Trans.tif
Traceback (most recent call last):
  File "d:\09_Code\Gis_Script\05_SAM\º‡Ã˝SAM.py", line 57, in process_file
    sam.predict(boxes=boxes, point_crs="EPSG:4326", output=output_path, dtype="uint8")
  File "D:\Wrz\anaconda\envs\GEE\Lib\site-packages\samgeo\samgeo.py", line 581, in predict
    if isinstance(coords[0], int):
                  ~~~~~~^^^
TypeError: 'NoneType' object is not subscriptable

Predict error file = D:\Dataset_and_Demo\2017-05-31_to_2017-09-15\00261_ADMeanFused_WithTiles_Trans.tif
Traceback (most recent call last):
  File "d:\09_Code\Gis_Script\05_SAM\º‡Ã˝SAM.py", line 57, in process_file
    sam.predict(boxes=boxes, point_crs="EPSG:4326", output=output_path, dtype="uint8")
  File "D:\Wrz\anaconda\envs\GEE\Lib\site-packages\samgeo\samgeo.py", line 581, in predict
    if isinstance(coords[0], int):
                  ~~~~~~^^^
TypeError: 'NoneType' object is not subscriptable

Predict error file = D:\Dataset_and_Demo\2017-05-31_to_2017-09-15\00263_ADMeanFused_WithTiles_Trans.tif
Traceback (most recent call last):
  File "d:\09_Code\Gis_Script\05_SAM\º‡Ã˝SAM.py", line 57, in process_file
    sam.predict(boxes=boxes, point_crs="EPSG:4326", output=output_path, dtype="uint8")
  File "D:\Wrz\anaconda\envs\GEE\Lib\site-packages\samgeo\samgeo.py", line 581, in predict
    if isinstance(coords[0], int):
                  ~~~~~~^^^
TypeError: 'NoneType' object is not subscriptable

Predict error file = D:\Dataset_and_Demo\2017-05-31_to_2017-09-15\00264_ADMeanFused_WithTiles_Trans.tif
Traceback (most recent call last):
  File "d:\09_Code\Gis_Script\05_SAM\º‡Ã˝SAM.py", line 57, in process_file
    sam.predict(boxes=boxes, point_crs="EPSG:4326", output=output_path, dtype="uint8")
  File "D:\Wrz\anaconda\envs\GEE\Lib\site-packages\samgeo\samgeo.py", line 581, in predict
    if isinstance(coords[0], int):
                  ~~~~~~^^^
TypeError: 'NoneType' object is not subscriptable

Predict error file = D:\Dataset_and_Demo\2017-05-31_to_2017-09-15\00269_ADMeanFused_WithTiles_Trans.tif
Traceback (most recent call last):
  File "d:\09_Code\Gis_Script\05_SAM\º‡Ã˝SAM.py", line 57, in process_file
    sam.predict(boxes=boxes, point_crs="EPSG:4326", output=output_path, dtype="uint8")
  File "D:\Wrz\anaconda\envs\GEE\Lib\site-packages\samgeo\samgeo.py", line 581, in predict
    if isinstance(coords[0], int):
                  ~~~~~~^^^
TypeError: 'NoneType' object is not subscriptable

Predict error file = D:\Dataset_and_Demo\2017-05-31_to_2017-09-15\00357_ADMeanFused_WithTiles_Trans.tif
Traceback (most recent call last):
  File "d:\09_Code\Gis_Script\05_SAM\º‡Ã˝SAM.py", line 57, in process_file
    sam.predict(boxes=boxes, point_crs="EPSG:4326", output=output_path, dtype="uint8")
  File "D:\Wrz\anaconda\envs\GEE\Lib\site-packages\samgeo\samgeo.py", line 581, in predict
    if isinstance(coords[0], int):
                  ~~~~~~^^^
TypeError: 'NoneType' object is not subscriptable

Predict error file = D:\Dataset_and_Demo\2017-09-15_to_2017-11-28\02675_ADMeanFused_Trans.tif
Traceback (most recent call last):
  File "d:\09_Code\Gis_Script\05_SAM\º‡Ã˝SAM.py", line 44, in process_file
    sam.set_image(input_path)
  File "D:\Wrz\anaconda\envs\GEE\Lib\site-packages\samgeo\samgeo.py", line 423, in set_image
    raise ValueError(f"Input path {image} does not exist.")
ValueError: Input path D:\Dataset_and_Demo\2017-09-15_to_2017-11-28\02675_ADMeanFused_Trans.tif does not exist.

Predict error file = D:\Dataset_and_Demo\2017-09-15_to_2017-11-28\02676_ADMeanFused_Trans.tif
Traceback (most recent call last):
  File "d:\09_Code\Gis_Script\05_SAM\º‡Ã˝SAM.py", line 44, in process_file
    sam.set_image(input_path)
  File "D:\Wrz\anaconda\envs\GEE\Lib\site-packages\samgeo\samgeo.py", line 423, in set_image
    raise ValueError(f"Input path {image} does not exist.")
ValueError: Input path D:\Dataset_and_Demo\2017-09-15_to_2017-11-28\02676_ADMeanFused_Trans.tif does not exist.

Predict error file = D:\Dataset_and_Demo\2017-09-15_to_2017-11-28\02718_ADMeanFused_Trans.tif
Traceback (most recent call last):
  File "d:\09_Code\Gis_Script\05_SAM\º‡Ã˝SAM.py", line 44, in process_file
    sam.set_image(input_path)
  File "D:\Wrz\anaconda\envs\GEE\Lib\site-packages\samgeo\samgeo.py", line 423, in set_image
    raise ValueError(f"Input path {image} does not exist.")
ValueError: Input path D:\Dataset_and_Demo\2017-09-15_to_2017-11-28\02718_ADMeanFused_Trans.tif does not exist.

Predict error file = D:\Dataset_and_Demo\2017-09-15_to_2017-11-28\02726_ADMeanFused_Trans.tif
Traceback (most recent call last):
  File "d:\09_Code\Gis_Script\05_SAM\º‡Ã˝SAM.py", line 44, in process_file
    sam.set_image(input_path)
  File "D:\Wrz\anaconda\envs\GEE\Lib\site-packages\samgeo\samgeo.py", line 423, in set_image
    raise ValueError(f"Input path {image} does not exist.")
ValueError: Input path D:\Dataset_and_Demo\2017-09-15_to_2017-11-28\02726_ADMeanFused_Trans.tif does not exist.

Predict error file = D:\Dataset_and_Demo\2017-09-15_to_2017-11-28\02729_ADMeanFused_Trans.tif
Traceback (most recent call last):
  File "d:\09_Code\Gis_Script\05_SAM\º‡Ã˝SAM.py", line 44, in process_file
    sam.set_image(input_path)
  File "D:\Wrz\anaconda\envs\GEE\Lib\site-packages\samgeo\samgeo.py", line 423, in set_image
    raise ValueError(f"Input path {image} does not exist.")
ValueError: Input path D:\Dataset_and_Demo\2017-09-15_to_2017-11-28\02729_ADMeanFused_Trans.tif does not exist.

Predict error file = D:\Dataset_and_Demo\2017-09-15_to_2017-11-28\02741_ADMeanFused_Trans.tif
Traceback (most recent call last):
  File "d:\09_Code\Gis_Script\05_SAM\º‡Ã˝SAM.py", line 44, in process_file
    sam.set_image(input_path)
  File "D:\Wrz\anaconda\envs\GEE\Lib\site-packages\samgeo\samgeo.py", line 423, in set_image
    raise ValueError(f"Input path {image} does not exist.")
ValueError: Input path D:\Dataset_and_Demo\2017-09-15_to_2017-11-28\02741_ADMeanFused_Trans.tif does not exist.

Predict error file = D:\Dataset_and_Demo\2017-09-15_to_2017-11-28\02749_ADMeanFused_Trans.tif
Traceback (most recent call last):
  File "d:\09_Code\Gis_Script\05_SAM\º‡Ã˝SAM.py", line 44, in process_file
    sam.set_image(input_path)
  File "D:\Wrz\anaconda\envs\GEE\Lib\site-packages\samgeo\samgeo.py", line 423, in set_image
    raise ValueError(f"Input path {image} does not exist.")
ValueError: Input path D:\Dataset_and_Demo\2017-09-15_to_2017-11-28\02749_ADMeanFused_Trans.tif does not exist.

Predict error file = D:\Dataset_and_Demo\2017-09-15_to_2017-11-28\02753_ADMeanFused_Trans.tif
Traceback (most recent call last):
  File "d:\09_Code\Gis_Script\05_SAM\º‡Ã˝SAM.py", line 44, in process_file
    sam.set_image(input_path)
  File "D:\Wrz\anaconda\envs\GEE\Lib\site-packages\samgeo\samgeo.py", line 423, in set_image
    raise ValueError(f"Input path {image} does not exist.")
ValueError: Input path D:\Dataset_and_Demo\2017-09-15_to_2017-11-28\02753_ADMeanFused_Trans.tif does not exist.

Predict error file = D:\Dataset_and_Demo\2017-09-15_to_2017-11-28\02789_ADMeanFused_Trans.tif
Traceback (most recent call last):
  File "d:\09_Code\Gis_Script\05_SAM\º‡Ã˝SAM.py", line 44, in process_file
    sam.set_image(input_path)
  File "D:\Wrz\anaconda\envs\GEE\Lib\site-packages\samgeo\samgeo.py", line 423, in set_image
    raise ValueError(f"Input path {image} does not exist.")
ValueError: Input path D:\Dataset_and_Demo\2017-09-15_to_2017-11-28\02789_ADMeanFused_Trans.tif does not exist.

Predict error file = D:\Dataset_and_Demo\2017-09-15_to_2017-11-28\02793_ADMeanFused_Trans.tif
Traceback (most recent call last):
  File "d:\09_Code\Gis_Script\05_SAM\º‡Ã˝SAM.py", line 44, in process_file
    sam.set_image(input_path)
  File "D:\Wrz\anaconda\envs\GEE\Lib\site-packages\samgeo\samgeo.py", line 423, in set_image
    raise ValueError(f"Input path {image} does not exist.")
ValueError: Input path D:\Dataset_and_Demo\2017-09-15_to_2017-11-28\02793_ADMeanFused_Trans.tif does not exist.

Predict error file = D:\Dataset_and_Demo\2017-09-15_to_2017-11-28\02801_ADMeanFused_Trans.tif
Traceback (most recent call last):
  File "d:\09_Code\Gis_Script\05_SAM\º‡Ã˝SAM.py", line 44, in process_file
    sam.set_image(input_path)
  File "D:\Wrz\anaconda\envs\GEE\Lib\site-packages\samgeo\samgeo.py", line 423, in set_image
    raise ValueError(f"Input path {image} does not exist.")
ValueError: Input path D:\Dataset_and_Demo\2017-09-15_to_2017-11-28\02801_ADMeanFused_Trans.tif does not exist.

Predict error file = D:\Dataset_and_Demo\2017-09-15_to_2017-11-28\02857_ADMeanFused_Trans.tif
Traceback (most recent call last):
  File "d:\09_Code\Gis_Script\05_SAM\º‡Ã˝SAM.py", line 44, in process_file
    sam.set_image(input_path)
  File "D:\Wrz\anaconda\envs\GEE\Lib\site-packages\samgeo\samgeo.py", line 423, in set_image
    raise ValueError(f"Input path {image} does not exist.")
ValueError: Input path D:\Dataset_and_Demo\2017-09-15_to_2017-11-28\02857_ADMeanFused_Trans.tif does not exist.

Predict error file = D:\Dataset_and_Demo\2017-09-15_to_2017-11-28\02860_ADMeanFused_Trans.tif
Traceback (most recent call last):
  File "d:\09_Code\Gis_Script\05_SAM\º‡Ã˝SAM.py", line 44, in process_file
    sam.set_image(input_path)
  File "D:\Wrz\anaconda\envs\GEE\Lib\site-packages\samgeo\samgeo.py", line 423, in set_image
    raise ValueError(f"Input path {image} does not exist.")
ValueError: Input path D:\Dataset_and_Demo\2017-09-15_to_2017-11-28\02860_ADMeanFused_Trans.tif does not exist.

Predict error file = D:\Dataset_and_Demo\2015-02-25_to_2015-05-31\04657_ADMeanFused_Trans.tif
Traceback (most recent call last):
  File "d:\09_Code\Gis_Script\05_SAM\º‡Ã˝SAM.py", line 51, in process_file
    AOI_Bound_Info = json.load(f)
                     ^^^^^^^^^^^^
  File "D:\Wrz\anaconda\envs\GEE\Lib\json\__init__.py", line 293, in load
    return loads(fp.read(),
           ^^^^^^^^^^^^^^^^
  File "D:\Wrz\anaconda\envs\GEE\Lib\json\__init__.py", line 346, in loads
    return _default_decoder.decode(s)
           ^^^^^^^^^^^^^^^^^^^^^^^^^^
  File "D:\Wrz\anaconda\envs\GEE\Lib\json\decoder.py", line 337, in decode
    obj, end = self.raw_decode(s, idx=_w(s, 0).end())
               ^^^^^^^^^^^^^^^^^^^^^^^^^^^^^^^^^^^^^^
  File "D:\Wrz\anaconda\envs\GEE\Lib\json\decoder.py", line 355, in raw_decode
    raise JSONDecodeError("Expecting value", s, err.value) from None
json.decoder.JSONDecodeError: Expecting value: line 1 column 1 (char 0)

Predict error file = D:\Dataset_and_Demo\2015-05-31_to_2015-09-15\00304_ADMeanFused_Trans.tif
Traceback (most recent call last):
  File "d:\09_Code\Gis_Script\05_SAM\º‡Ã˝SAM.py", line 51, in process_file
    AOI_Bound_Info = json.load(f)
                     ^^^^^^^^^^^^
  File "D:\Wrz\anaconda\envs\GEE\Lib\json\__init__.py", line 293, in load
    return loads(fp.read(),
           ^^^^^^^^^^^^^^^^
  File "D:\Wrz\anaconda\envs\GEE\Lib\json\__init__.py", line 346, in loads
    return _default_decoder.decode(s)
           ^^^^^^^^^^^^^^^^^^^^^^^^^^
  File "D:\Wrz\anaconda\envs\GEE\Lib\json\decoder.py", line 337, in decode
    obj, end = self.raw_decode(s, idx=_w(s, 0).end())
               ^^^^^^^^^^^^^^^^^^^^^^^^^^^^^^^^^^^^^^
  File "D:\Wrz\anaconda\envs\GEE\Lib\json\decoder.py", line 355, in raw_decode
    raise JSONDecodeError("Expecting value", s, err.value) from None
json.decoder.JSONDecodeError: Expecting value: line 1 column 1 (char 0)

Predict error file = D:\Dataset_and_Demo\2015-05-31_to_2015-09-15\00306_ADMeanFused_Trans.tif
Traceback (most recent call last):
  File "d:\09_Code\Gis_Script\05_SAM\º‡Ã˝SAM.py", line 51, in process_file
    AOI_Bound_Info = json.load(f)
                     ^^^^^^^^^^^^
  File "D:\Wrz\anaconda\envs\GEE\Lib\json\__init__.py", line 293, in load
    return loads(fp.read(),
           ^^^^^^^^^^^^^^^^
  File "D:\Wrz\anaconda\envs\GEE\Lib\json\__init__.py", line 346, in loads
    return _default_decoder.decode(s)
           ^^^^^^^^^^^^^^^^^^^^^^^^^^
  File "D:\Wrz\anaconda\envs\GEE\Lib\json\decoder.py", line 337, in decode
    obj, end = self.raw_decode(s, idx=_w(s, 0).end())
               ^^^^^^^^^^^^^^^^^^^^^^^^^^^^^^^^^^^^^^
  File "D:\Wrz\anaconda\envs\GEE\Lib\json\decoder.py", line 355, in raw_decode
    raise JSONDecodeError("Expecting value", s, err.value) from None
json.decoder.JSONDecodeError: Expecting value: line 1 column 1 (char 0)

Predict error file = D:\Dataset_and_Demo\2015-09-15_to_2015-11-28\01791_ADMeanFused_Trans.tif
Traceback (most recent call last):
  File "d:\09_Code\Gis_Script\05_SAM\º‡Ã˝SAM.py", line 51, in process_file
    AOI_Bound_Info = json.load(f)
                     ^^^^^^^^^^^^
  File "D:\Wrz\anaconda\envs\GEE\Lib\json\__init__.py", line 293, in load
    return loads(fp.read(),
           ^^^^^^^^^^^^^^^^
  File "D:\Wrz\anaconda\envs\GEE\Lib\json\__init__.py", line 346, in loads
    return _default_decoder.decode(s)
           ^^^^^^^^^^^^^^^^^^^^^^^^^^
  File "D:\Wrz\anaconda\envs\GEE\Lib\json\decoder.py", line 337, in decode
    obj, end = self.raw_decode(s, idx=_w(s, 0).end())
               ^^^^^^^^^^^^^^^^^^^^^^^^^^^^^^^^^^^^^^
  File "D:\Wrz\anaconda\envs\GEE\Lib\json\decoder.py", line 355, in raw_decode
    raise JSONDecodeError("Expecting value", s, err.value) from None
json.decoder.JSONDecodeError: Expecting value: line 1 column 1 (char 0)

Predict error file = D:\Dataset_and_Demo\2016-09-15_to_2016-11-28\01047_ADMeanFused_WithTiles_Trans.tif
Traceback (most recent call last):
  File "d:\09_Code\Gis_Script\05_SAM\º‡Ã˝SAM.py", line 45, in process_file
    sam.set_image(input_path)
  File "D:\Wrz\anaconda\envs\GEE\Lib\site-packages\samgeo\samgeo.py", line 423, in set_image
    raise ValueError(f"Input path {image} does not exist.")
ValueError: Input path D:\Dataset_and_Demo\2016-09-15_to_2016-11-28\01047_ADMeanFused_WithTiles_Trans.tif does not exist.

Predict error file = D:\Dataset_and_Demo\2016-09-15_to_2016-11-28\02153_ADMeanFused_Trans.tif
Traceback (most recent call last):
  File "d:\09_Code\Gis_Script\05_SAM\º‡Ã˝SAM.py", line 51, in process_file
    AOI_Bound_Info = json.load(f)
                     ^^^^^^^^^^^^
  File "D:\Wrz\anaconda\envs\GEE\Lib\json\__init__.py", line 293, in load
    return loads(fp.read(),
           ^^^^^^^^^^^^^^^^
  File "D:\Wrz\anaconda\envs\GEE\Lib\json\__init__.py", line 346, in loads
    return _default_decoder.decode(s)
           ^^^^^^^^^^^^^^^^^^^^^^^^^^
  File "D:\Wrz\anaconda\envs\GEE\Lib\json\decoder.py", line 337, in decode
    obj, end = self.raw_decode(s, idx=_w(s, 0).end())
               ^^^^^^^^^^^^^^^^^^^^^^^^^^^^^^^^^^^^^^
  File "D:\Wrz\anaconda\envs\GEE\Lib\json\decoder.py", line 355, in raw_decode
    raise JSONDecodeError("Expecting value", s, err.value) from None
json.decoder.JSONDecodeError: Expecting value: line 1 column 1 (char 0)

Predict error file = D:\Dataset_and_Demo\2017-09-15_to_2017-11-28\00452_ADMeanFused_WithTiles_Trans.tif
Traceback (most recent call last):
  File "d:\09_Code\Gis_Script\05_SAM\º‡Ã˝SAM.py", line 45, in process_file
    sam.set_image(input_path)
  File "D:\Wrz\anaconda\envs\GEE\Lib\site-packages\samgeo\samgeo.py", line 423, in set_image
    raise ValueError(f"Input path {image} does not exist.")
ValueError: Input path D:\Dataset_and_Demo\2017-09-15_to_2017-11-28\00452_ADMeanFused_WithTiles_Trans.tif does not exist.

Predict error file = D:\Dataset_and_Demo\2017-09-15_to_2017-11-28\01110_ADMeanFused_WithTiles_Trans.tif
Traceback (most recent call last):
  File "d:\09_Code\Gis_Script\05_SAM\º‡Ã˝SAM.py", line 45, in process_file
    sam.set_image(input_path)
  File "D:\Wrz\anaconda\envs\GEE\Lib\site-packages\samgeo\samgeo.py", line 423, in set_image
    raise ValueError(f"Input path {image} does not exist.")
ValueError: Input path D:\Dataset_and_Demo\2017-09-15_to_2017-11-28\01110_ADMeanFused_WithTiles_Trans.tif does not exist.

Predict error file = D:\Dataset_and_Demo\2017-09-15_to_2017-11-28\02653_ADMeanFused_WithTiles_Trans.tif
Traceback (most recent call last):
  File "d:\09_Code\Gis_Script\05_SAM\º‡Ã˝SAM.py", line 45, in process_file
    sam.set_image(input_path)
  File "D:\Wrz\anaconda\envs\GEE\Lib\site-packages\samgeo\samgeo.py", line 423, in set_image
    raise ValueError(f"Input path {image} does not exist.")
ValueError: Input path D:\Dataset_and_Demo\2017-09-15_to_2017-11-28\02653_ADMeanFused_WithTiles_Trans.tif does not exist.

Predict error file = D:\Dataset_and_Demo\2017-09-15_to_2017-11-28\03323_ADMeanFused_Trans.tif
Traceback (most recent call last):
  File "d:\09_Code\Gis_Script\05_SAM\º‡Ã˝SAM.py", line 51, in process_file
    AOI_Bound_Info = json.load(f)
                     ^^^^^^^^^^^^
  File "D:\Wrz\anaconda\envs\GEE\Lib\json\__init__.py", line 293, in load
    return loads(fp.read(),
           ^^^^^^^^^^^^^^^^
  File "D:\Wrz\anaconda\envs\GEE\Lib\json\__init__.py", line 346, in loads
    return _default_decoder.decode(s)
           ^^^^^^^^^^^^^^^^^^^^^^^^^^
  File "D:\Wrz\anaconda\envs\GEE\Lib\json\decoder.py", line 337, in decode
    obj, end = self.raw_decode(s, idx=_w(s, 0).end())
               ^^^^^^^^^^^^^^^^^^^^^^^^^^^^^^^^^^^^^^
  File "D:\Wrz\anaconda\envs\GEE\Lib\json\decoder.py", line 355, in raw_decode
    raise JSONDecodeError("Expecting value", s, err.value) from None
json.decoder.JSONDecodeError: Expecting value: line 1 column 1 (char 0)

Predict error file = D:\Dataset_and_Demo\2017-11-28_to_2018-02-25\03806_ADMeanFused_Trans.tif
Traceback (most recent call last):
  File "d:\09_Code\Gis_Script\05_SAM\º‡Ã˝SAM.py", line 51, in process_file
    AOI_Bound_Info = json.load(f)
                     ^^^^^^^^^^^^
  File "D:\Wrz\anaconda\envs\GEE\Lib\json\__init__.py", line 293, in load
    return loads(fp.read(),
           ^^^^^^^^^^^^^^^^
  File "D:\Wrz\anaconda\envs\GEE\Lib\json\__init__.py", line 346, in loads
    return _default_decoder.decode(s)
           ^^^^^^^^^^^^^^^^^^^^^^^^^^
  File "D:\Wrz\anaconda\envs\GEE\Lib\json\decoder.py", line 337, in decode
    obj, end = self.raw_decode(s, idx=_w(s, 0).end())
               ^^^^^^^^^^^^^^^^^^^^^^^^^^^^^^^^^^^^^^
  File "D:\Wrz\anaconda\envs\GEE\Lib\json\decoder.py", line 355, in raw_decode
    raise JSONDecodeError("Expecting value", s, err.value) from None
json.decoder.JSONDecodeError: Expecting value: line 1 column 1 (char 0)

Predict error file = D:\Dataset_and_Demo\2018-05-31_to_2018-09-15\04713_ADMeanFused_Trans.tif
Traceback (most recent call last):
  File "d:\09_Code\Gis_Script\05_SAM\º‡Ã˝SAM.py", line 51, in process_file
    AOI_Bound_Info = json.load(f)
                     ^^^^^^^^^^^^
  File "D:\Wrz\anaconda\envs\GEE\Lib\json\__init__.py", line 293, in load
    return loads(fp.read(),
           ^^^^^^^^^^^^^^^^
  File "D:\Wrz\anaconda\envs\GEE\Lib\json\__init__.py", line 346, in loads
    return _default_decoder.decode(s)
           ^^^^^^^^^^^^^^^^^^^^^^^^^^
  File "D:\Wrz\anaconda\envs\GEE\Lib\json\decoder.py", line 337, in decode
    obj, end = self.raw_decode(s, idx=_w(s, 0).end())
               ^^^^^^^^^^^^^^^^^^^^^^^^^^^^^^^^^^^^^^
  File "D:\Wrz\anaconda\envs\GEE\Lib\json\decoder.py", line 355, in raw_decode
    raise JSONDecodeError("Expecting value", s, err.value) from None
json.decoder.JSONDecodeError: Expecting value: line 1 column 1 (char 0)

Predict error file = D:\Dataset_and_Demo\2019-09-15_to_2019-11-28\00434_ADMeanFused_WithTiles_Trans.tif
Traceback (most recent call last):
  File "d:\09_Code\Gis_Script\05_SAM\º‡Ã˝SAM.py", line 58, in process_file
    sam.predict(boxes=boxes, point_crs="EPSG:4326", output=output_path, dtype="uint8")
  File "D:\Wrz\anaconda\envs\GEE\Lib\site-packages\samgeo\samgeo.py", line 581, in predict
    if isinstance(coords[0], int):
                  ~~~~~~^^^
TypeError: 'NoneType' object is not subscriptable

Predict error file = D:\Dataset_and_Demo\2019-09-15_to_2019-11-28\00526_ADMeanFused_WithTiles_Trans.tif
Traceback (most recent call last):
  File "d:\09_Code\Gis_Script\05_SAM\º‡Ã˝SAM.py", line 58, in process_file
    sam.predict(boxes=boxes, point_crs="EPSG:4326", output=output_path, dtype="uint8")
  File "D:\Wrz\anaconda\envs\GEE\Lib\site-packages\samgeo\samgeo.py", line 581, in predict
    if isinstance(coords[0], int):
                  ~~~~~~^^^
TypeError: 'NoneType' object is not subscriptable

Predict error file = D:\Dataset_and_Demo\2019-11-28_to_2020-02-25\00488_ADMeanFused_Trans.tif
Traceback (most recent call last):
  File "d:\09_Code\Gis_Script\05_SAM\º‡Ã˝SAM.py", line 51, in process_file
    AOI_Bound_Info = json.load(f)
                     ^^^^^^^^^^^^
  File "D:\Wrz\anaconda\envs\GEE\Lib\json\__init__.py", line 293, in load
    return loads(fp.read(),
           ^^^^^^^^^^^^^^^^
  File "D:\Wrz\anaconda\envs\GEE\Lib\json\__init__.py", line 346, in loads
    return _default_decoder.decode(s)
           ^^^^^^^^^^^^^^^^^^^^^^^^^^
  File "D:\Wrz\anaconda\envs\GEE\Lib\json\decoder.py", line 337, in decode
    obj, end = self.raw_decode(s, idx=_w(s, 0).end())
               ^^^^^^^^^^^^^^^^^^^^^^^^^^^^^^^^^^^^^^
  File "D:\Wrz\anaconda\envs\GEE\Lib\json\decoder.py", line 355, in raw_decode
    raise JSONDecodeError("Expecting value", s, err.value) from None
json.decoder.JSONDecodeError: Expecting value: line 1 column 1 (char 0)

Predict error file = D:\Dataset_and_Demo\2015-02-25_to_2015-05-31\04657_ADMeanFused_Trans.tif
Traceback (most recent call last):
  File "d:\09_Code\Gis_Script\05_SAM\º‡Ã˝SAM.py", line 51, in process_file
    AOI_Bound_Info = json.load(f)
                     ^^^^^^^^^^^^
  File "D:\Wrz\anaconda\envs\GEE\Lib\json\__init__.py", line 293, in load
    return loads(fp.read(),
           ^^^^^^^^^^^^^^^^
  File "D:\Wrz\anaconda\envs\GEE\Lib\json\__init__.py", line 346, in loads
    return _default_decoder.decode(s)
           ^^^^^^^^^^^^^^^^^^^^^^^^^^
  File "D:\Wrz\anaconda\envs\GEE\Lib\json\decoder.py", line 337, in decode
    obj, end = self.raw_decode(s, idx=_w(s, 0).end())
               ^^^^^^^^^^^^^^^^^^^^^^^^^^^^^^^^^^^^^^
  File "D:\Wrz\anaconda\envs\GEE\Lib\json\decoder.py", line 355, in raw_decode
    raise JSONDecodeError("Expecting value", s, err.value) from None
json.decoder.JSONDecodeError: Expecting value: line 1 column 1 (char 0)

Predict error file = D:\Dataset_and_Demo\2015-05-31_to_2015-09-15\00304_ADMeanFused_Trans.tif
Traceback (most recent call last):
  File "d:\09_Code\Gis_Script\05_SAM\º‡Ã˝SAM.py", line 51, in process_file
    AOI_Bound_Info = json.load(f)
                     ^^^^^^^^^^^^
  File "D:\Wrz\anaconda\envs\GEE\Lib\json\__init__.py", line 293, in load
    return loads(fp.read(),
           ^^^^^^^^^^^^^^^^
  File "D:\Wrz\anaconda\envs\GEE\Lib\json\__init__.py", line 346, in loads
    return _default_decoder.decode(s)
           ^^^^^^^^^^^^^^^^^^^^^^^^^^
  File "D:\Wrz\anaconda\envs\GEE\Lib\json\decoder.py", line 337, in decode
    obj, end = self.raw_decode(s, idx=_w(s, 0).end())
               ^^^^^^^^^^^^^^^^^^^^^^^^^^^^^^^^^^^^^^
  File "D:\Wrz\anaconda\envs\GEE\Lib\json\decoder.py", line 355, in raw_decode
    raise JSONDecodeError("Expecting value", s, err.value) from None
json.decoder.JSONDecodeError: Expecting value: line 1 column 1 (char 0)

Predict error file = D:\Dataset_and_Demo\2015-05-31_to_2015-09-15\00306_ADMeanFused_Trans.tif
Traceback (most recent call last):
  File "d:\09_Code\Gis_Script\05_SAM\º‡Ã˝SAM.py", line 51, in process_file
    AOI_Bound_Info = json.load(f)
                     ^^^^^^^^^^^^
  File "D:\Wrz\anaconda\envs\GEE\Lib\json\__init__.py", line 293, in load
    return loads(fp.read(),
           ^^^^^^^^^^^^^^^^
  File "D:\Wrz\anaconda\envs\GEE\Lib\json\__init__.py", line 346, in loads
    return _default_decoder.decode(s)
           ^^^^^^^^^^^^^^^^^^^^^^^^^^
  File "D:\Wrz\anaconda\envs\GEE\Lib\json\decoder.py", line 337, in decode
    obj, end = self.raw_decode(s, idx=_w(s, 0).end())
               ^^^^^^^^^^^^^^^^^^^^^^^^^^^^^^^^^^^^^^
  File "D:\Wrz\anaconda\envs\GEE\Lib\json\decoder.py", line 355, in raw_decode
    raise JSONDecodeError("Expecting value", s, err.value) from None
json.decoder.JSONDecodeError: Expecting value: line 1 column 1 (char 0)

Predict error file = D:\Dataset_and_Demo\2015-09-15_to_2015-11-28\01791_ADMeanFused_Trans.tif
Traceback (most recent call last):
  File "d:\09_Code\Gis_Script\05_SAM\º‡Ã˝SAM.py", line 51, in process_file
    AOI_Bound_Info = json.load(f)
                     ^^^^^^^^^^^^
  File "D:\Wrz\anaconda\envs\GEE\Lib\json\__init__.py", line 293, in load
    return loads(fp.read(),
           ^^^^^^^^^^^^^^^^
  File "D:\Wrz\anaconda\envs\GEE\Lib\json\__init__.py", line 346, in loads
    return _default_decoder.decode(s)
           ^^^^^^^^^^^^^^^^^^^^^^^^^^
  File "D:\Wrz\anaconda\envs\GEE\Lib\json\decoder.py", line 337, in decode
    obj, end = self.raw_decode(s, idx=_w(s, 0).end())
               ^^^^^^^^^^^^^^^^^^^^^^^^^^^^^^^^^^^^^^
  File "D:\Wrz\anaconda\envs\GEE\Lib\json\decoder.py", line 355, in raw_decode
    raise JSONDecodeError("Expecting value", s, err.value) from None
json.decoder.JSONDecodeError: Expecting value: line 1 column 1 (char 0)

Predict error file = D:\Dataset_and_Demo\2016-09-15_to_2016-11-28\02153_ADMeanFused_Trans.tif
Traceback (most recent call last):
  File "d:\09_Code\Gis_Script\05_SAM\º‡Ã˝SAM.py", line 51, in process_file
    AOI_Bound_Info = json.load(f)
                     ^^^^^^^^^^^^
  File "D:\Wrz\anaconda\envs\GEE\Lib\json\__init__.py", line 293, in load
    return loads(fp.read(),
           ^^^^^^^^^^^^^^^^
  File "D:\Wrz\anaconda\envs\GEE\Lib\json\__init__.py", line 346, in loads
    return _default_decoder.decode(s)
           ^^^^^^^^^^^^^^^^^^^^^^^^^^
  File "D:\Wrz\anaconda\envs\GEE\Lib\json\decoder.py", line 337, in decode
    obj, end = self.raw_decode(s, idx=_w(s, 0).end())
               ^^^^^^^^^^^^^^^^^^^^^^^^^^^^^^^^^^^^^^
  File "D:\Wrz\anaconda\envs\GEE\Lib\json\decoder.py", line 355, in raw_decode
    raise JSONDecodeError("Expecting value", s, err.value) from None
json.decoder.JSONDecodeError: Expecting value: line 1 column 1 (char 0)

Predict error file = D:\Dataset_and_Demo\2016-11-28_to_2017-02-25\04623_ADMeanFused_Trans.tif
Traceback (most recent call last):
  File "d:\09_Code\Gis_Script\05_SAM\º‡Ã˝SAM.py", line 51, in process_file
    AOI_Bound_Info = json.load(f)
                     ^^^^^^^^^^^^
  File "D:\Wrz\anaconda\envs\GEE\Lib\json\__init__.py", line 293, in load
    return loads(fp.read(),
           ^^^^^^^^^^^^^^^^
  File "D:\Wrz\anaconda\envs\GEE\Lib\json\__init__.py", line 346, in loads
    return _default_decoder.decode(s)
           ^^^^^^^^^^^^^^^^^^^^^^^^^^
  File "D:\Wrz\anaconda\envs\GEE\Lib\json\decoder.py", line 337, in decode
    obj, end = self.raw_decode(s, idx=_w(s, 0).end())
               ^^^^^^^^^^^^^^^^^^^^^^^^^^^^^^^^^^^^^^
  File "D:\Wrz\anaconda\envs\GEE\Lib\json\decoder.py", line 355, in raw_decode
    raise JSONDecodeError("Expecting value", s, err.value) from None
json.decoder.JSONDecodeError: Expecting value: line 1 column 1 (char 0)

Predict error file = D:\Dataset_and_Demo\2017-09-15_to_2017-11-28\03323_ADMeanFused_Trans.tif
Traceback (most recent call last):
  File "d:\09_Code\Gis_Script\05_SAM\º‡Ã˝SAM.py", line 51, in process_file
    AOI_Bound_Info = json.load(f)
                     ^^^^^^^^^^^^
  File "D:\Wrz\anaconda\envs\GEE\Lib\json\__init__.py", line 293, in load
    return loads(fp.read(),
           ^^^^^^^^^^^^^^^^
  File "D:\Wrz\anaconda\envs\GEE\Lib\json\__init__.py", line 346, in loads
    return _default_decoder.decode(s)
           ^^^^^^^^^^^^^^^^^^^^^^^^^^
  File "D:\Wrz\anaconda\envs\GEE\Lib\json\decoder.py", line 337, in decode
    obj, end = self.raw_decode(s, idx=_w(s, 0).end())
               ^^^^^^^^^^^^^^^^^^^^^^^^^^^^^^^^^^^^^^
  File "D:\Wrz\anaconda\envs\GEE\Lib\json\decoder.py", line 355, in raw_decode
    raise JSONDecodeError("Expecting value", s, err.value) from None
json.decoder.JSONDecodeError: Expecting value: line 1 column 1 (char 0)

Predict error file = D:\Dataset_and_Demo\2017-11-28_to_2018-02-25\03806_ADMeanFused_Trans.tif
Traceback (most recent call last):
  File "d:\09_Code\Gis_Script\05_SAM\º‡Ã˝SAM.py", line 51, in process_file
    AOI_Bound_Info = json.load(f)
                     ^^^^^^^^^^^^
  File "D:\Wrz\anaconda\envs\GEE\Lib\json\__init__.py", line 293, in load
    return loads(fp.read(),
           ^^^^^^^^^^^^^^^^
  File "D:\Wrz\anaconda\envs\GEE\Lib\json\__init__.py", line 346, in loads
    return _default_decoder.decode(s)
           ^^^^^^^^^^^^^^^^^^^^^^^^^^
  File "D:\Wrz\anaconda\envs\GEE\Lib\json\decoder.py", line 337, in decode
    obj, end = self.raw_decode(s, idx=_w(s, 0).end())
               ^^^^^^^^^^^^^^^^^^^^^^^^^^^^^^^^^^^^^^
  File "D:\Wrz\anaconda\envs\GEE\Lib\json\decoder.py", line 355, in raw_decode
    raise JSONDecodeError("Expecting value", s, err.value) from None
json.decoder.JSONDecodeError: Expecting value: line 1 column 1 (char 0)

Predict error file = D:\Dataset_and_Demo\2018-05-31_to_2018-09-15\04713_ADMeanFused_Trans.tif
Traceback (most recent call last):
  File "d:\09_Code\Gis_Script\05_SAM\º‡Ã˝SAM.py", line 51, in process_file
    AOI_Bound_Info = json.load(f)
                     ^^^^^^^^^^^^
  File "D:\Wrz\anaconda\envs\GEE\Lib\json\__init__.py", line 293, in load
    return loads(fp.read(),
           ^^^^^^^^^^^^^^^^
  File "D:\Wrz\anaconda\envs\GEE\Lib\json\__init__.py", line 346, in loads
    return _default_decoder.decode(s)
           ^^^^^^^^^^^^^^^^^^^^^^^^^^
  File "D:\Wrz\anaconda\envs\GEE\Lib\json\decoder.py", line 337, in decode
    obj, end = self.raw_decode(s, idx=_w(s, 0).end())
               ^^^^^^^^^^^^^^^^^^^^^^^^^^^^^^^^^^^^^^
  File "D:\Wrz\anaconda\envs\GEE\Lib\json\decoder.py", line 355, in raw_decode
    raise JSONDecodeError("Expecting value", s, err.value) from None
json.decoder.JSONDecodeError: Expecting value: line 1 column 1 (char 0)

Predict error file = D:\Dataset_and_Demo\2019-09-15_to_2019-11-28\00434_ADMeanFused_WithTiles_Trans.tif
Traceback (most recent call last):
  File "d:\09_Code\Gis_Script\05_SAM\º‡Ã˝SAM.py", line 58, in process_file
    sam.predict(boxes=boxes, point_crs="EPSG:4326", output=output_path, dtype="uint8")
  File "D:\Wrz\anaconda\envs\GEE\Lib\site-packages\samgeo\samgeo.py", line 581, in predict
    if isinstance(coords[0], int):
                  ~~~~~~^^^
TypeError: 'NoneType' object is not subscriptable

Predict error file = D:\Dataset_and_Demo\2019-09-15_to_2019-11-28\00526_ADMeanFused_WithTiles_Trans.tif
Traceback (most recent call last):
  File "d:\09_Code\Gis_Script\05_SAM\º‡Ã˝SAM.py", line 58, in process_file
    sam.predict(boxes=boxes, point_crs="EPSG:4326", output=output_path, dtype="uint8")
  File "D:\Wrz\anaconda\envs\GEE\Lib\site-packages\samgeo\samgeo.py", line 581, in predict
    if isinstance(coords[0], int):
                  ~~~~~~^^^
TypeError: 'NoneType' object is not subscriptable

Predict error file = D:\Dataset_and_Demo\2019-11-28_to_2020-02-25\00488_ADMeanFused_Trans.tif
Traceback (most recent call last):
  File "d:\09_Code\Gis_Script\05_SAM\º‡Ã˝SAM.py", line 51, in process_file
    AOI_Bound_Info = json.load(f)
                     ^^^^^^^^^^^^
  File "D:\Wrz\anaconda\envs\GEE\Lib\json\__init__.py", line 293, in load
    return loads(fp.read(),
           ^^^^^^^^^^^^^^^^
  File "D:\Wrz\anaconda\envs\GEE\Lib\json\__init__.py", line 346, in loads
    return _default_decoder.decode(s)
           ^^^^^^^^^^^^^^^^^^^^^^^^^^
  File "D:\Wrz\anaconda\envs\GEE\Lib\json\decoder.py", line 337, in decode
    obj, end = self.raw_decode(s, idx=_w(s, 0).end())
               ^^^^^^^^^^^^^^^^^^^^^^^^^^^^^^^^^^^^^^
  File "D:\Wrz\anaconda\envs\GEE\Lib\json\decoder.py", line 355, in raw_decode
    raise JSONDecodeError("Expecting value", s, err.value) from None
json.decoder.JSONDecodeError: Expecting value: line 1 column 1 (char 0)

Predict error file = D:\Dataset_and_Demo\2020-05-31_to_2020-09-15\02626_ADMeanFused_WithTiles_Trans.tif
Traceback (most recent call last):
  File "d:\09_Code\Gis_Script\05_SAM\º‡Ã˝SAM.py", line 58, in process_file
    sam.predict(boxes=boxes, point_crs="EPSG:4326", output=output_path, dtype="uint8")
  File "D:\Wrz\anaconda\envs\GEE\Lib\site-packages\samgeo\samgeo.py", line 581, in predict
    if isinstance(coords[0], int):
                  ~~~~~~^^^
TypeError: 'NoneType' object is not subscriptable

Predict error file = D:\Dataset_and_Demo\2020-05-31_to_2020-09-15\04308_ADMeanFused_WithTiles_Trans.tif
Traceback (most recent call last):
  File "d:\09_Code\Gis_Script\05_SAM\º‡Ã˝SAM.py", line 58, in process_file
    sam.predict(boxes=boxes, point_crs="EPSG:4326", output=output_path, dtype="uint8")
  File "D:\Wrz\anaconda\envs\GEE\Lib\site-packages\samgeo\samgeo.py", line 581, in predict
    if isinstance(coords[0], int):
                  ~~~~~~^^^
TypeError: 'NoneType' object is not subscriptable

Predict error file = D:\Dataset_and_Demo\2020-05-31_to_2020-09-15\04768_ADMeanFused_WithTiles_Trans.tif
Traceback (most recent call last):
  File "d:\09_Code\Gis_Script\05_SAM\º‡Ã˝SAM.py", line 58, in process_file
    sam.predict(boxes=boxes, point_crs="EPSG:4326", output=output_path, dtype="uint8")
  File "D:\Wrz\anaconda\envs\GEE\Lib\site-packages\samgeo\samgeo.py", line 581, in predict
    if isinstance(coords[0], int):
                  ~~~~~~^^^
TypeError: 'NoneType' object is not subscriptable

Predict error file = D:\Dataset_and_Demo\2020-09-15_to_2020-11-28\00008_ADMeanFused_Trans.tif
Traceback (most recent call last):
  File "d:\09_Code\Gis_Script\05_SAM\º‡Ã˝SAM.py", line 51, in process_file
    AOI_Bound_Info = json.load(f)
                     ^^^^^^^^^^^^
  File "D:\Wrz\anaconda\envs\GEE\Lib\json\__init__.py", line 293, in load
    return loads(fp.read(),
           ^^^^^^^^^^^^^^^^
  File "D:\Wrz\anaconda\envs\GEE\Lib\json\__init__.py", line 346, in loads
    return _default_decoder.decode(s)
           ^^^^^^^^^^^^^^^^^^^^^^^^^^
  File "D:\Wrz\anaconda\envs\GEE\Lib\json\decoder.py", line 337, in decode
    obj, end = self.raw_decode(s, idx=_w(s, 0).end())
               ^^^^^^^^^^^^^^^^^^^^^^^^^^^^^^^^^^^^^^
  File "D:\Wrz\anaconda\envs\GEE\Lib\json\decoder.py", line 355, in raw_decode
    raise JSONDecodeError("Expecting value", s, err.value) from None
json.decoder.JSONDecodeError: Expecting value: line 1 column 1 (char 0)

Predict error file = D:\Dataset_and_Demo\2020-09-15_to_2020-11-28\00533_ADMeanFused_Trans.tif
Traceback (most recent call last):
  File "d:\09_Code\Gis_Script\05_SAM\º‡Ã˝SAM.py", line 51, in process_file
    AOI_Bound_Info = json.load(f)
                     ^^^^^^^^^^^^
  File "D:\Wrz\anaconda\envs\GEE\Lib\json\__init__.py", line 293, in load
    return loads(fp.read(),
           ^^^^^^^^^^^^^^^^
  File "D:\Wrz\anaconda\envs\GEE\Lib\json\__init__.py", line 346, in loads
    return _default_decoder.decode(s)
           ^^^^^^^^^^^^^^^^^^^^^^^^^^
  File "D:\Wrz\anaconda\envs\GEE\Lib\json\decoder.py", line 337, in decode
    obj, end = self.raw_decode(s, idx=_w(s, 0).end())
               ^^^^^^^^^^^^^^^^^^^^^^^^^^^^^^^^^^^^^^
  File "D:\Wrz\anaconda\envs\GEE\Lib\json\decoder.py", line 355, in raw_decode
    raise JSONDecodeError("Expecting value", s, err.value) from None
json.decoder.JSONDecodeError: Expecting value: line 1 column 1 (char 0)

Predict error file = D:\Dataset_and_Demo\2018-11-28_to_2019-02-25\00990_ADMeanFused_Trans.tif
Traceback (most recent call last):
  File "d:\09_Code\Gis_Script\05_SAM\º‡Ã˝SAM.py", line 51, in process_file
    AOI_Bound_Info = json.load(f)
                     ^^^^^^^^^^^^
  File "D:\Wrz\anaconda\envs\GEE\Lib\json\__init__.py", line 293, in load
    return loads(fp.read(),
           ^^^^^^^^^^^^^^^^
  File "D:\Wrz\anaconda\envs\GEE\Lib\json\__init__.py", line 346, in loads
    return _default_decoder.decode(s)
           ^^^^^^^^^^^^^^^^^^^^^^^^^^
  File "D:\Wrz\anaconda\envs\GEE\Lib\json\decoder.py", line 337, in decode
    obj, end = self.raw_decode(s, idx=_w(s, 0).end())
               ^^^^^^^^^^^^^^^^^^^^^^^^^^^^^^^^^^^^^^
  File "D:\Wrz\anaconda\envs\GEE\Lib\json\decoder.py", line 355, in raw_decode
    raise JSONDecodeError("Expecting value", s, err.value) from None
json.decoder.JSONDecodeError: Expecting value: line 1 column 1 (char 0)

Predict error file = D:\Dataset_and_Demo\2018-11-28_to_2019-02-25\01757_ADMeanFused_Trans.tif
Traceback (most recent call last):
  File "d:\09_Code\Gis_Script\05_SAM\º‡Ã˝SAM.py", line 51, in process_file
    AOI_Bound_Info = json.load(f)
                     ^^^^^^^^^^^^
  File "D:\Wrz\anaconda\envs\GEE\Lib\json\__init__.py", line 293, in load
    return loads(fp.read(),
           ^^^^^^^^^^^^^^^^
  File "D:\Wrz\anaconda\envs\GEE\Lib\json\__init__.py", line 346, in loads
    return _default_decoder.decode(s)
           ^^^^^^^^^^^^^^^^^^^^^^^^^^
  File "D:\Wrz\anaconda\envs\GEE\Lib\json\decoder.py", line 337, in decode
    obj, end = self.raw_decode(s, idx=_w(s, 0).end())
               ^^^^^^^^^^^^^^^^^^^^^^^^^^^^^^^^^^^^^^
  File "D:\Wrz\anaconda\envs\GEE\Lib\json\decoder.py", line 355, in raw_decode
    raise JSONDecodeError("Expecting value", s, err.value) from None
json.decoder.JSONDecodeError: Expecting value: line 1 column 1 (char 0)

Predict error file = D:\Dataset_and_Demo\2018-11-28_to_2019-02-25\01933_ADMeanFused_Trans.tif
Traceback (most recent call last):
  File "d:\09_Code\Gis_Script\05_SAM\º‡Ã˝SAM.py", line 51, in process_file
    AOI_Bound_Info = json.load(f)
                     ^^^^^^^^^^^^
  File "D:\Wrz\anaconda\envs\GEE\Lib\json\__init__.py", line 293, in load
    return loads(fp.read(),
           ^^^^^^^^^^^^^^^^
  File "D:\Wrz\anaconda\envs\GEE\Lib\json\__init__.py", line 346, in loads
    return _default_decoder.decode(s)
           ^^^^^^^^^^^^^^^^^^^^^^^^^^
  File "D:\Wrz\anaconda\envs\GEE\Lib\json\decoder.py", line 337, in decode
    obj, end = self.raw_decode(s, idx=_w(s, 0).end())
               ^^^^^^^^^^^^^^^^^^^^^^^^^^^^^^^^^^^^^^
  File "D:\Wrz\anaconda\envs\GEE\Lib\json\decoder.py", line 355, in raw_decode
    raise JSONDecodeError("Expecting value", s, err.value) from None
json.decoder.JSONDecodeError: Expecting value: line 1 column 1 (char 0)

Predict error file = D:\Dataset_and_Demo\2018-11-28_to_2019-02-25\02142_ADMeanFused_Trans.tif
Traceback (most recent call last):
  File "d:\09_Code\Gis_Script\05_SAM\º‡Ã˝SAM.py", line 51, in process_file
    AOI_Bound_Info = json.load(f)
                     ^^^^^^^^^^^^
  File "D:\Wrz\anaconda\envs\GEE\Lib\json\__init__.py", line 293, in load
    return loads(fp.read(),
           ^^^^^^^^^^^^^^^^
  File "D:\Wrz\anaconda\envs\GEE\Lib\json\__init__.py", line 346, in loads
    return _default_decoder.decode(s)
           ^^^^^^^^^^^^^^^^^^^^^^^^^^
  File "D:\Wrz\anaconda\envs\GEE\Lib\json\decoder.py", line 337, in decode
    obj, end = self.raw_decode(s, idx=_w(s, 0).end())
               ^^^^^^^^^^^^^^^^^^^^^^^^^^^^^^^^^^^^^^
  File "D:\Wrz\anaconda\envs\GEE\Lib\json\decoder.py", line 355, in raw_decode
    raise JSONDecodeError("Expecting value", s, err.value) from None
json.decoder.JSONDecodeError: Expecting value: line 1 column 1 (char 0)

Predict error file = D:\Dataset_and_Demo\2018-11-28_to_2019-02-25\02849_ADMeanFused_Trans.tif
Traceback (most recent call last):
  File "d:\09_Code\Gis_Script\05_SAM\º‡Ã˝SAM.py", line 51, in process_file
    AOI_Bound_Info = json.load(f)
                     ^^^^^^^^^^^^
  File "D:\Wrz\anaconda\envs\GEE\Lib\json\__init__.py", line 293, in load
    return loads(fp.read(),
           ^^^^^^^^^^^^^^^^
  File "D:\Wrz\anaconda\envs\GEE\Lib\json\__init__.py", line 346, in loads
    return _default_decoder.decode(s)
           ^^^^^^^^^^^^^^^^^^^^^^^^^^
  File "D:\Wrz\anaconda\envs\GEE\Lib\json\decoder.py", line 337, in decode
    obj, end = self.raw_decode(s, idx=_w(s, 0).end())
               ^^^^^^^^^^^^^^^^^^^^^^^^^^^^^^^^^^^^^^
  File "D:\Wrz\anaconda\envs\GEE\Lib\json\decoder.py", line 355, in raw_decode
    raise JSONDecodeError("Expecting value", s, err.value) from None
json.decoder.JSONDecodeError: Expecting value: line 1 column 1 (char 0)

Predict error file = D:\Dataset_and_Demo\2018-11-28_to_2019-02-25\02862_ADMeanFused_WithTiles_Trans.tif
Traceback (most recent call last):
  File "d:\09_Code\Gis_Script\05_SAM\º‡Ã˝SAM.py", line 51, in process_file
    AOI_Bound_Info = json.load(f)
                     ^^^^^^^^^^^^
  File "D:\Wrz\anaconda\envs\GEE\Lib\json\__init__.py", line 293, in load
    return loads(fp.read(),
           ^^^^^^^^^^^^^^^^
  File "D:\Wrz\anaconda\envs\GEE\Lib\json\__init__.py", line 346, in loads
    return _default_decoder.decode(s)
           ^^^^^^^^^^^^^^^^^^^^^^^^^^
  File "D:\Wrz\anaconda\envs\GEE\Lib\json\decoder.py", line 337, in decode
    obj, end = self.raw_decode(s, idx=_w(s, 0).end())
               ^^^^^^^^^^^^^^^^^^^^^^^^^^^^^^^^^^^^^^
  File "D:\Wrz\anaconda\envs\GEE\Lib\json\decoder.py", line 355, in raw_decode
    raise JSONDecodeError("Expecting value", s, err.value) from None
json.decoder.JSONDecodeError: Expecting value: line 1 column 1 (char 0)

Predict error file = D:\Dataset_and_Demo\2019-05-31_to_2019-09-15\00446_ADMeanFused_Trans.tif
Traceback (most recent call last):
  File "d:\09_Code\Gis_Script\05_SAM\º‡Ã˝SAM.py", line 51, in process_file
    AOI_Bound_Info = json.load(f)
                     ^^^^^^^^^^^^
  File "D:\Wrz\anaconda\envs\GEE\Lib\json\__init__.py", line 293, in load
    return loads(fp.read(),
           ^^^^^^^^^^^^^^^^
  File "D:\Wrz\anaconda\envs\GEE\Lib\json\__init__.py", line 346, in loads
    return _default_decoder.decode(s)
           ^^^^^^^^^^^^^^^^^^^^^^^^^^
  File "D:\Wrz\anaconda\envs\GEE\Lib\json\decoder.py", line 337, in decode
    obj, end = self.raw_decode(s, idx=_w(s, 0).end())
               ^^^^^^^^^^^^^^^^^^^^^^^^^^^^^^^^^^^^^^
  File "D:\Wrz\anaconda\envs\GEE\Lib\json\decoder.py", line 355, in raw_decode
    raise JSONDecodeError("Expecting value", s, err.value) from None
json.decoder.JSONDecodeError: Expecting value: line 1 column 1 (char 0)

Predict error file = D:\Dataset_and_Demo\2019-05-31_to_2019-09-15\00505_ADMeanFused_Trans.tif
Traceback (most recent call last):
  File "d:\09_Code\Gis_Script\05_SAM\º‡Ã˝SAM.py", line 51, in process_file
    AOI_Bound_Info = json.load(f)
                     ^^^^^^^^^^^^
  File "D:\Wrz\anaconda\envs\GEE\Lib\json\__init__.py", line 293, in load
    return loads(fp.read(),
           ^^^^^^^^^^^^^^^^
  File "D:\Wrz\anaconda\envs\GEE\Lib\json\__init__.py", line 346, in loads
    return _default_decoder.decode(s)
           ^^^^^^^^^^^^^^^^^^^^^^^^^^
  File "D:\Wrz\anaconda\envs\GEE\Lib\json\decoder.py", line 337, in decode
    obj, end = self.raw_decode(s, idx=_w(s, 0).end())
               ^^^^^^^^^^^^^^^^^^^^^^^^^^^^^^^^^^^^^^
  File "D:\Wrz\anaconda\envs\GEE\Lib\json\decoder.py", line 355, in raw_decode
    raise JSONDecodeError("Expecting value", s, err.value) from None
json.decoder.JSONDecodeError: Expecting value: line 1 column 1 (char 0)

Predict error file = D:\Dataset_and_Demo\2021-02-25_to_2021-05-31\00630_ADMeanFused_Trans.tif
Traceback (most recent call last):
  File "d:\09_Code\Gis_Script\05_SAM\º‡Ã˝SAM.py", line 51, in process_file
    AOI_Bound_Info = json.load(f)
                     ^^^^^^^^^^^^
  File "D:\Wrz\anaconda\envs\GEE\Lib\json\__init__.py", line 293, in load
    return loads(fp.read(),
           ^^^^^^^^^^^^^^^^
  File "D:\Wrz\anaconda\envs\GEE\Lib\json\__init__.py", line 346, in loads
    return _default_decoder.decode(s)
           ^^^^^^^^^^^^^^^^^^^^^^^^^^
  File "D:\Wrz\anaconda\envs\GEE\Lib\json\decoder.py", line 337, in decode
    obj, end = self.raw_decode(s, idx=_w(s, 0).end())
               ^^^^^^^^^^^^^^^^^^^^^^^^^^^^^^^^^^^^^^
  File "D:\Wrz\anaconda\envs\GEE\Lib\json\decoder.py", line 355, in raw_decode
    raise JSONDecodeError("Expecting value", s, err.value) from None
json.decoder.JSONDecodeError: Expecting value: line 1 column 1 (char 0)

Predict error file = D:\Dataset_and_Demo\2021-02-25_to_2021-05-31\02129_ADMeanFused_Trans.tif
Traceback (most recent call last):
  File "d:\09_Code\Gis_Script\05_SAM\º‡Ã˝SAM.py", line 51, in process_file
    AOI_Bound_Info = json.load(f)
                     ^^^^^^^^^^^^
  File "D:\Wrz\anaconda\envs\GEE\Lib\json\__init__.py", line 293, in load
    return loads(fp.read(),
           ^^^^^^^^^^^^^^^^
  File "D:\Wrz\anaconda\envs\GEE\Lib\json\__init__.py", line 346, in loads
    return _default_decoder.decode(s)
           ^^^^^^^^^^^^^^^^^^^^^^^^^^
  File "D:\Wrz\anaconda\envs\GEE\Lib\json\decoder.py", line 337, in decode
    obj, end = self.raw_decode(s, idx=_w(s, 0).end())
               ^^^^^^^^^^^^^^^^^^^^^^^^^^^^^^^^^^^^^^
  File "D:\Wrz\anaconda\envs\GEE\Lib\json\decoder.py", line 355, in raw_decode
    raise JSONDecodeError("Expecting value", s, err.value) from None
json.decoder.JSONDecodeError: Expecting value: line 1 column 1 (char 0)

Predict error file = D:\Dataset_and_Demo\2021-05-31_to_2021-09-15\00498_ADMeanFused_Trans.tif
Traceback (most recent call last):
  File "d:\09_Code\Gis_Script\05_SAM\º‡Ã˝SAM.py", line 51, in process_file
    AOI_Bound_Info = json.load(f)
                     ^^^^^^^^^^^^
  File "D:\Wrz\anaconda\envs\GEE\Lib\json\__init__.py", line 293, in load
    return loads(fp.read(),
           ^^^^^^^^^^^^^^^^
  File "D:\Wrz\anaconda\envs\GEE\Lib\json\__init__.py", line 346, in loads
    return _default_decoder.decode(s)
           ^^^^^^^^^^^^^^^^^^^^^^^^^^
  File "D:\Wrz\anaconda\envs\GEE\Lib\json\decoder.py", line 337, in decode
    obj, end = self.raw_decode(s, idx=_w(s, 0).end())
               ^^^^^^^^^^^^^^^^^^^^^^^^^^^^^^^^^^^^^^
  File "D:\Wrz\anaconda\envs\GEE\Lib\json\decoder.py", line 355, in raw_decode
    raise JSONDecodeError("Expecting value", s, err.value) from None
json.decoder.JSONDecodeError: Expecting value: line 1 column 1 (char 0)

Predict error file = D:\Dataset_and_Demo\2020-11-28_to_2021-02-25\03101_ADMeanFused_Trans.tif
Traceback (most recent call last):
  File "d:\09_Code\Gis_Script\05_SAM\º‡Ã˝SAM.py", line 51, in process_file
    AOI_Bound_Info = json.load(f)
                     ^^^^^^^^^^^^
  File "D:\Wrz\anaconda\envs\GEE\Lib\json\__init__.py", line 293, in load
    return loads(fp.read(),
           ^^^^^^^^^^^^^^^^
  File "D:\Wrz\anaconda\envs\GEE\Lib\json\__init__.py", line 346, in loads
    return _default_decoder.decode(s)
           ^^^^^^^^^^^^^^^^^^^^^^^^^^
  File "D:\Wrz\anaconda\envs\GEE\Lib\json\decoder.py", line 337, in decode
    obj, end = self.raw_decode(s, idx=_w(s, 0).end())
               ^^^^^^^^^^^^^^^^^^^^^^^^^^^^^^^^^^^^^^
  File "D:\Wrz\anaconda\envs\GEE\Lib\json\decoder.py", line 355, in raw_decode
    raise JSONDecodeError("Expecting value", s, err.value) from None
json.decoder.JSONDecodeError: Expecting value: line 1 column 1 (char 0)

